Workbook

Sheet ASSUMPTIONS
A1: JD BRITT — FINANCIAL PLAN ASSUMPTIONS
A2: Ivory cell = editable input (change freely) White = formula (do not edit) Green text = cross-sheet reference (edit on source sheet) Underlined header = click to navigate
A3: Assumption | B3: PATH A Military → Retire → PhD | C3: PATH B Separate → CS / Tech Job | D3: PATH C Separate → PhD → Research | E3: Source / Notes | F3: ↳ Feeds PROJECTIONS | G3: ⟵ Source Sheet
A4: SERVICE & TIMELINE
A5: TAFMS Date (entered service) | B5: Feb 2014 | C5: Feb 2014 | D5: Feb 2014 | E5: Resume / service records
A6: Current Year (base year) | B6: 2026 | C6: 2026 | D6: 2026 | E6: Projection start year
A7: Current Age (at projection start) | B7: 36 | C7: 36 | D7: 36 | E7: Born ~1990; joined at 24 in Feb 2014
A8: Path A: Military Retirement Year | B8: 2034 | C8: N/A | D8: N/A | E8: Feb 2014 + 20 yrs service = Feb 2034
A9: Path B/C: Separation Year | B9: N/A | C9: 2027 | D9: 2027 | E9: Nov 2027 if CNODP not accepted
A10: Years of Active Service (at 2026) | B10: 12.1 | C10: 12.1 | D10: 12.1 | E10: 2026 − 2014
A11: CURRENT COMPENSATION SNAPSHOT (read-only — edit values on INCOME sheet)
A12: Base Pay (Monthly) | B12: =INCOME!B6 -> 5591.66 | C12: =INCOME!B6 -> 5591.66 | D12: =INCOME!B6 -> 5591.66 | E12: From INCOME sheet | F12: → Gross Income (all paths, active duty) | G12: View in INCOME sheet → Base Pay row
A13: BAH — Housing Allowance (Monthly) | B13: =INCOME!B7 -> 2741.66 | C13: =INCOME!B7 -> 2741.66 | D13: =INCOME!B7 -> 2741.66 | E13: Tax-free; from INCOME | F13: → Tax-Free Income (BAH, active duty) | G13: View in INCOME sheet → BAH row
A14: BAS — Food Allowance (Monthly) | B14: =INCOME!B8 -> 477 | C14: =INCOME!B8 -> 477 | D14: =INCOME!B8 -> 477 | E14: Tax-free; from INCOME | F14: → Tax-Free Income (BAS, active duty) | G14: View in INCOME sheet → BAS row
A15: Gross Monthly Income (Current) | B15: =INCOME!B97 -> 8810.32 | C15: =INCOME!B97 -> 8810.32 | D15: =INCOME!B97 -> 8810.32 | E15: INCOME!B97 — all income | F15: Info only — not projected directly | G15: View in INCOME sheet → Gross Total
A16: Net Monthly Income (Current) | B16: =INCOME!B99 -> 7720.37 | C16: =INCOME!B99 -> 7720.37 | D16: =INCOME!B99 -> 7720.37 | E16: INCOME!B99 — after deductions | F16: Info only — not projected directly | G16: View in INCOME sheet → Net Total
A17: MILITARY RETIREMENT & PENSION (Path A only)
A18: Retirement System | B18: High-3 | C18: N/A | D18: N/A | E18: Pre-2018 entry → High-3 (not BRS)
A19: High-3 Avg Base Pay (est. at retirement) | B19: 7266 | C19: 0 | D19: 0 | E19: Est. E-8 avg of highest 36-mo base pay at 20 yrs (2024 tables). Source: dfas.mil
A20: Pension Multiplier (2.5% × 20 yrs) | B20: 0.5 | C20: 0 | D20: 0 | E20: 2.5% × 20 = 50%
A21: Monthly Pension (before tax) | B21: =B19*B20 -> 3633 | C21: 0 | D21: 0 | E21: High-3 × multiplier | F21: → Path A Gross Income (pension, yr 9+)
A22: Annual Pension | B22: =B21*12 -> 43596 | C22: 0 | D22: 0 | E22: Monthly × 12
A23: Pension COLA (annual increase) | B23: 0.028 | C23: 0 | D23: 0 | E23: 2026 COLA: 2.8%. Long-term avg ~2.5%. Source: militarypay.defense.gov | F23: → Path A Gross Income (pension COLA rate)
A24: Pension Start Year | B24: 2034 | C24: N/A | D24: N/A | E24: Retire at 44 (entered at 24; 20 yrs service)
A25: HEALTHCARE COSTS
A26: TRICARE Retiree Annual Cost (Path A) | B26: 182 | C26: N/A | D26: N/A | E26: 2025 TRICARE Select Group A: $181.92/yr. Source: tricare.mil | F26: → Path A Healthcare (TRICARE, yr 9+)
A27: TRICARE Annual Increase Rate (Path A) | B27: 0.03 | C27: N/A | D27: N/A | E27: ~3%/yr Congressional adjustment | F27: → Path A Healthcare (TRICARE inflation)
A28: Civilian Health Insurance Annual | B28: N/A | C28: 3000 | D28: 0 | E28: Path B: employer-sponsored ~$3K OOP. Path C: PhD = university-covered ($0). Source: KFF 2025 | F28: → Path B Healthcare (yr 2+) → Path C Healthcare (yr 8+)
A29: Civilian Healthcare Inflation | B29: N/A | C29: 0.08 | D29: 0.08 | E29: ~8%/yr. Source: Covered California 2026 avg | F29: → Path B/C Healthcare (inflation rate)
A30: Gap Year Health Insurance (Path C) | B30: N/A | C30: N/A | D30: 3000 | E30: Path C gap year: marketplace plan ~$3K. Source: healthcare.gov estimates | F30: → Path C Healthcare (gap year only)
A31: VA DISABILITY & BENEFITS
A32: Assumed VA Disability Rating | B32: 0.3 | C32: 0.3 | D32: 0.3 | E32: 30% conservative est. — common for 12+ yrs. Actual unknown until filed. Source: va.gov
A33: VA Disability Monthly Payment (2026) | B33: =IF(ISBLANK(B88),552.47,IF(B88="Yes",B90,0)) -> 552.47 | C33: =IF(ISBLANK(C88),552.47,IF(C88="Yes",B90,0)) -> 552.47 | D33: =IF(ISBLANK(D88),552.47,IF(D88="Yes",B90,0)) -> 552.47 | E33: 30% single, no dep: $537.42 (2025) + 2.8% COLA = $552.47. Source: va.gov | F33: → Tax-Free Income: VA disability (all paths)
A34: VA Disability COLA (annual) | B34: 0.028 | C34: 0.028 | D34: 0.028 | E34: 2026 COLA: 2.8%. Source: va.gov | F34: → Tax-Free Income: VA COLA rate (all paths)
A35: VA Disability Start Year (est.) | B35: 2034 | C35: 2028 | D35: 2028 | E35: Path A: at retirement. Path B/C: at separation Nov 2027 → effective 2028
A36: POST-9/11 GI BILL
A37: GI Bill Eligibility (months) | B37: 36 | C37: 36 | D37: 36 | E37: Forever GI Bill — no expiration
A38: GI Bill BAH Monthly (Bay Area rate) | B38: =IF(B95="CUSTOM",4992,B97) -> 4992 | C38: 0 | D38: =IF(B95="CUSTOM",4992,B97) -> 4992 | E38: Bay Area (94305): $4,992/mo. Path B: not used for school. Source: va.gov BAH calculator | F38: → Tax-Free Income: GI Bill BAH Path A: yrs 9-13 | Path C: yrs 3-7
A39: GI Bill Book Stipend (annual) | B39: 1000 | C39: 0 | D39: 1000 | E39: $1,000/yr for books. Path B: N/A | F39: → Tax-Free Income: GI Bill books (same years as BAH)
A40: GI Bill Stacks with PhD Stipend? | B40: YES | C40: N/A | D40: YES | E40: Universities do NOT reduce stipend for GI Bill. Source: SCO confirmation
...

Sheet CAREER_DATA
A1: CAREER DATA — Compensation Reference Tables
A3: TABLE 1 — PATH B: CS/TECH COMPANY OPTIONS (Immediate CS career — No PhD)
A4: Company ID | B4: Display Name / Label | C4: Role Type | D4: Base Salary | E4: Annual Bonus (% of base) | F4: Annual RSU | G4: Growth Rate | H4: Total Comp (Year 1) | I4: Notes / Source
A5: GENERIC_IC | B5: Generic Big Tech IC | C5: SWE/IC L3-equiv | D5: 117638 | E5: 0.1 | F5: 20000 | G5: 0.04 | H5: =D5+D5*E5+F5 -> 149401.8 | I5: Current default. Reflects typical non-PhD IC at mid-tier big tech. Source: levels.fyi 2026
A6: MSFT_SWE | B6: Microsoft SWE (L62-63) | C6: SWE / IC | D6: 175000 | E6: 0.15 | F6: 90000 | G6: 0.04 | H6: =D6+D6*E6+F6 -> 291250 | I6: Source: levels.fyi 2026 median; L62-63 range $291K median TC
A7: GOOG_SWE | B7: Google SWE (L4-L5) | C7: SWE / IC | D7: 190000 | E7: 0.15 | F7: 110000 | G7: 0.04 | H7: =D7+D7*E7+F7 -> 328500 | I7: Source: levels.fyi 2026; L4-L5 range $329K median TC
A8: NVDA_IC | B8: NVIDIA (IC4-IC5) | C8: SWE / Systems | D8: 195000 | E8: 0.15 | F8: 150000 | G8: 0.05 | H8: =D8+D8*E8+F8 -> 374250 | I8: Source: levels.fyi 2026; IC4-5 range, median TC ~$374K. Strong AI/hardware pipeline
A9: INTEL_IC | B9: Intel (Grade 7-8) | C9: Systems / HW | D9: 155000 | E9: 0.1 | F9: 40000 | G9: 0.03 | H9: =D9+D9*E9+F9 -> 210500 | I9: Source: levels.fyi 2026; Grade 7-8 range, median TC ~$211K. Intel Labs entry point
A10: STARTUP_TECH | B10: Tech Startup (funded) | C10: SWE / ML Eng | D10: 140000 | E10: 0.05 | F10: 40000 | G10: 0.05 | H10: =D10+D10*E10+F10 -> 187000 | I10: Estimate: seed-to-series B startup. Equity varies widely. ±$30K on base
A12: TABLE 2 — POST-PhD RESEARCH SCIENTIST EMPLOYER OPTIONS (Paths A & C after PhD)
A13: Company ID | B13: Display Name / Label | C13: Role Type | D13: Base Salary | E13: Annual Bonus (% of base) | F13: Annual RSU | G13: Growth Rate | H13: Total Comp (Year 1) | I13: Notes / Source
A14: CONSERVATIVE | B14: Conservative / Default | C14: Research Scientist | D14: 220000 | E14: 0.1 | F14: 30000 | G14: 0.04 | H14: =D14+D14*E14+F14 -> 272000 | I14: Default model assumption. Realistic floor for PhD-holders at established labs. Source: Internal estimate
A15: INTEL_LABS | B15: Intel Labs | C15: Research Scientist | D15: 190000 | E15: 0.1 | F15: 50000 | G15: 0.03 | H15: =D15+D15*E15+F15 -> 259000 | I15: Source: levels.fyi 2026; median TC ~$274K. Neuromorphic/Loihi lab aligned with BCI goals. Intel Folsom team relevant
A16: NEURALINK | B16: Neuralink | C16: Research Eng./Sci. | D16: 185000 | E16: 0.1 | F16: 60000 | G16: 0.04 | H16: =D16+D16*E16+F16 -> 263500 | I16: Source: levels.fyi 2026; total comp ~$261K. BCI-direct alignment. Equity component variable. Elon Musk risk factor
A17: MSFT_RESEARCH | B17: Microsoft Research | C17: Research Scientist | D17: 200000 | E17: 0.15 | F17: 80000 | G17: 0.04 | H17: =D17+D17*E17+F17 -> 310000 | I17: Source: levels.fyi 2026; median TC ~$310K. Strong AI/ML research. MSR has BCI-adjacent work (Project Rio, etc.)
A18: DEEPMIND | B18: Google DeepMind | C18: Research Scientist | D18: 230000 | E18: 0.15 | F18: 120000 | G18: 0.04 | H18: =D18+D18*E18+F18 -> 384500 | I18: Source: levels.fyi 2026; median TC ~$373K. Premier AI research lab. PhD pipeline to DeepMind strong for BCI/neuro
A19: NVDA_RESEARCH | B19: NVIDIA Research | C19: Research Scientist | D19: 250000 | E19: 0.15 | F19: 150000 | G19: 0.05 | H19: =D19+D19*E19+F19 -> 437500 | I19: Source: levels.fyi 2026; median TC ~$438K. AI/ML research growing rapidly. Neuromorphics + robotics alignment
A20: ANTHROPIC | B20: Anthropic | C20: Research Scientist | D20: 400000 | E20: 0 | F20: 100000 | G20: 0.05 | H20: =D20+D20*E20+F20 -> 500000 | I20: Source: levels.fyi 2026; median TC ~$746K (high equity). $400K base is conservative planning estimate. Alignment research
A22: TABLE 3 — VA DISABILITY RATES (2026, Veteran Alone, No Dependents — 2.8% COLA)
A23: Rating % | B23: Monthly 2026 | C23: Annual 2026 | D23: Notes
A24: 0% | B24: 0 | C24: =B24*12 -> 0 | D24: 0% rating — no compensation
A25: 10% | B25: 180.42 | C25: =B25*12 -> 2165.04 | D25: 2026 rate. No increase for dependents at 10-20%
A26: 20% | B26: 356 | C26: =B26*12 -> 4272 | D26: 2026 rate (estimated 2.8% COLA from 2025). Source: va.gov
A27: 30% | B27: 552.47 | C27: =B27*12 -> 6629.64 | D27: 2026 confirmed rate. Source: va.gov / ASSUMPTIONS row 33
A28: 40% | B28: 795.84 | C28: =B28*12 -> 9550.08 | D28: 2026 rate. Source: va.gov/disability/compensation-rates
A29: 50% | B29: 1132.9 | C29: =B29*12 -> 13594.8 | D29: 2026 rate. Source: va.gov
A30: 60% | B30: 1435.01 | C30: =B30*12 -> 17220.12 | D30: 2026 rate. Source: va.gov
A31: 70% | B31: 1808.44 | C31: =B31*12 -> 21701.28 | D31: 2026 rate. Source: va.gov
A32: 80% | B32: 2102.14 | C32: =B32*12 -> 25225.68 | D32: 2026 rate. Source: va.gov
A33: 90% | B33: 2362.3 | C33: =B33*12 -> 28347.6 | D33: 2026 rate. Source: va.gov
A34: 100% | B34: 3938.57 | C34: =B34*12 -> 47262.84 | D34: 2026 rate (P&T / Total). Source: va.gov. Additional SMC may apply
A36: SELECTOR RANGES — These named areas are referenced by ASSUMPTIONS dropdowns
A37: B Company IDs (B5:B10): | B37: GENERIC_IC,MSFT_SWE,GOOG_SWE,NVDA_IC,INTEL_IC,STARTUP_TECH
A38: PhD Employer IDs (B14:B20): | B38: CONSERVATIVE,INTEL_LABS,NEURALINK,MSFT_RESEARCH,DEEPMIND,NVDA_RESEARCH,ANTHROPIC
A39: VA Rating % (A24:A34): | B39: 0%,10%,20%,30%,40%,50%,60%,70%,80%,90%,100%

Sheet SCHOOL_DATA
A1: SCHOOL DATA — PhD Program Financial Reference (Paths A & C)
A3: TABLE 1 — GRAD SCHOOL FINANCIAL DATA (Stipend, GI Bill BAH, State Tax, Housing)
A4: Program ID | B4: School | C4: Location | D4: State | E4: Stipend/Yr | F4: GI Bill BAH /Month | G4: GI Bill Eligible? | H4: Univ Health Covered? | I4: Est. Rent /Month | J4: State Tax Rate | K4: App Fee | L4: Notes / Source
A5: STAN-CS-PHD | B5: Stanford | C5: Stanford, CA | D5: CA | E5: 57000 | F5: 4992 | G5: Yes | H5: Yes | I5: 2800 | J5: 0.07 | K5: 125 | L5: Stipend ~$57K/yr (2025-26). BAH: zip 94305, $4,992/mo confirmed va.gov. Yellow Ribbon covers tuition. Source: cs.stanford.edu, va.gov
A6: UCB-EECS-PHD | B6: UC Berkeley | C6: Berkeley, CA | D6: CA | E6: 44000 | F6: 4992 | G6: Yes | H6: Yes | I6: 2600 | J6: 0.07 | K6: 135 | L6: Stipend ~$44K/yr. BAH: Berkeley same zone as Stanford ($4,992). In-state tuition waived for PhD. Source: eecs.berkeley.edu, va.gov
A7: MIT-EECS-PHD | B7: MIT | C7: Cambridge, MA | D7: MA | E7: 56340 | F7: 3513 | G7: Yes | H7: Yes | I7: 2400 | J7: 0.05 | K7: 90 | L7: Stipend $4,695/mo ($56.3K/yr). BAH: Cambridge MA zip 02139 = $3,513/mo confirmed. MA flat tax 5%. Source: eecs.mit.edu, va.gov
A8: CMU-SCS-PHD | B8: CMU | C8: Pittsburgh, PA | D8: PA | E8: 42900 | F8: 1400 | G8: Yes | H8: Yes | I8: 1200 | J8: 0.031 | K8: 100 | L8: Stipend ~$42.9K/yr. BAH: Pittsburgh zip 15213 = $1,400/mo confirmed (significant disadvantage vs Bay Area). PA flat tax 3.07%. Source: csd.cs.cmu.edu, va.gov
A9: UW-CSE-PHD | B9: UW | C9: Seattle, WA | D9: WA | E9: 38000 | F9: 3200 | G9: Yes | H9: Yes | I9: 2000 | J9: 0 | K9: 90 | L9: Stipend RA/TA ~$38K/yr. BAH: Seattle WA ~$3,200/mo estimated (2026). WA has NO state income tax. Source: cs.washington.edu, va.gov est.
A10: UCD-CS-PHD | B10: UC Davis | C10: Davis, CA | D10: CA | E10: 39800 | F10: 1980 | G10: Yes | H10: Yes | I10: 1400 | J10: 0.07 | K10: 135 | L10: Stipend GSR/TA ~$39.8K/yr. BAH: Davis CA zip 95616 ~$1,980/mo est. Accessible from Sacramento. Source: cs.ucdavis.edu, va.gov est.
A11: IST-IGPC-MD | B11: Science Tokyo | C11: Tokyo, Japan | D11: N/A | E11: 13200 | F11: 0 | G11: No | H11: Yes | I11: 800 | J11: 0 | K11: 200 | L11: MEXT scholarship: JPY 148,000/mo (~$1,100 USD). Not eligible for US GI Bill. State tax N/A. Source: isct.ac.jp, mext.go.jp
A12: CAM-CS-PHD | B12: Cambridge | C12: Cambridge, UK | D12: N/A | E12: 25200 | F12: 0 | G12: No | H12: Yes | I12: 1600 | J12: 0 | K12: 25 | L12: Maintenance ~GBP 19,237/yr (~$25.2K USD). Not eligible for US GI Bill. Gates Cambridge funding option. Source: cst.cam.ac.uk
A13: CUSTOM | B13: Custom / Other | C13: — | D13: — | E13: 47000 | F13: 4992 | G13: Yes | H13: Yes | I13: 2500 | J13: 0.07 | K13: 0 | L13: Default custom option. Uses current ASSUMPTIONS values. Override stipend/BAH manually in ASSUMPTIONS rows 46 and 38.
A15: School IDs for dropdown (A5:A13): | B15: STAN-CS-PHD,UCB-EECS-PHD,MIT-EECS-PHD,CMU-SCS-PHD,UW-CSE-PHD,UCD-CS-PHD,IST-IGPC-MD,CAM-CS-PHD,CUSTOM

Sheet PROJECTIONS
A1: JD BRITT — 50-YEAR FINANCIAL PROJECTION | Three Paths: Military Retirement vs. CS/Tech vs. Grad School → Research
A2: All projections driven by ASSUMPTIONS sheet. Pension, VA disability, and GI Bill are tax-free income. Portfolio = prior × 7% + retirement savings + 20% of positive net cash flow.
D3: PATH A — Military → Retire 2034 → PhD → Research Scientist | M3: PATH B — Separate Nov 2027 → CS / Tech Job (immediate) | V3: PATH C — Separate Nov 2027 → Gap Year → PhD → Research Scientist | AE3: COMPARISON (A advantage over B and C)
A4: Yr # | B4: Year | C4: Age | D4: =HYPERLINK("#ASSUMPTIONS!A4","Status") -> Status | E4: =HYPERLINK("#ASSUMPTIONS!B42","Gross Income") -> Gross Income | F4: =HYPERLINK("#ASSUMPTIONS!B31","Tax-Free Income") -> Tax-Free Income | G4: =HYPERLINK("#ASSUMPTIONS!B63","Taxes") -> Taxes | H4: =HYPERLINK("#ASSUMPTIONS!B25","Healthcare") -> Healthcare | I4: =HYPERLINK("#ASSUMPTIONS!B68","Living Expenses") -> Living Expenses | J4: =HYPERLINK("#ASSUMPTIONS!B53","Ret. Savings") -> Ret. Savings | K4: =HYPERLINK("#ASSUMPTIONS!A4","Net Cash Flow") -> Net Cash Flow | L4: =HYPERLINK("#ASSUMPTIONS!B53","Portfolio") -> Portfolio | M4: =HYPERLINK("#ASSUMPTIONS!A4","Status") -> Status | N4: =HYPERLINK("#ASSUMPTIONS!B42","Gross Income") -> Gross Income | O4: =HYPERLINK("#ASSUMPTIONS!B31","Tax-Free Income") -> Tax-Free Income | P4: =HYPERLINK("#ASSUMPTIONS!B63","Taxes") -> Taxes | Q4: =HYPERLINK("#ASSUMPTIONS!B25","Healthcare") -> Healthcare | R4: =HYPERLINK("#ASSUMPTIONS!B68","Living Expenses") -> Living Expenses | S4: =HYPERLINK("#ASSUMPTIONS!B53","Ret. Savings") -> Ret. Savings | T4: =HYPERLINK("#ASSUMPTIONS!A4","Net Cash Flow") -> Net Cash Flow | U4: =HYPERLINK("#ASSUMPTIONS!B53","Portfolio") -> Portfolio | V4: =HYPERLINK("#ASSUMPTIONS!A4","Status") -> Status | W4: =HYPERLINK("#ASSUMPTIONS!B42","Gross Income") -> Gross Income | X4: =HYPERLINK("#ASSUMPTIONS!B31","Tax-Free Income") -> Tax-Free Income | Y4: =HYPERLINK("#ASSUMPTIONS!B63","Taxes") -> Taxes | Z4: =HYPERLINK("#ASSUMPTIONS!B25","Healthcare") -> Healthcare | AA4: =HYPERLINK("#ASSUMPTIONS!B68","Living Expenses") -> Living Expenses | AB4: =HYPERLINK("#ASSUMPTIONS!B53","Ret. Savings") -> Ret. Savings | AC4: =HYPERLINK("#ASSUMPTIONS!A4","Net Cash Flow") -> Net Cash Flow | AD4: =HYPERLINK("#ASSUMPTIONS!B53","Portfolio") -> Portfolio | AE4: A vs B Income | AF4: A vs C Income | AG4: A vs B Portfolio | AH4: A vs C Portfolio
A5: 0 | B5: 2026 | C5: 36 | D5: Active Duty | E5: =ASSUMPTIONS!$B$12*12*(1+ASSUMPTIONS!$B$52)^0 -> 67099.92 | F5: =(ASSUMPTIONS!$B$13+ASSUMPTIONS!$B$14)*12*(1+ASSUMPTIONS!$B$52)^0 -> 38623.92 | G5: =MAX((E5-F5)*(ASSUMPTIONS!$B$64+ASSUMPTIONS!$B$67),0) -> 5410.44 | H5: 0 | I5: =ASSUMPTIONS!$B$70*12*(1+ASSUMPTIONS!$B$71)^0 -> 28725.84 | J5: =ASSUMPTIONS!$B$60*12 -> 22800 | K5: =E5+F5-G5-H5-I5-J5 -> 48787.56 | L5: =ASSUMPTIONS!$B$58*(1+ASSUMPTIONS!$B$59)+J5+MAX(K5,0)*0.2 -> 228367.51 | M5: Active Duty | N5: =ASSUMPTIONS!$B$12*12*(1+ASSUMPTIONS!$B$52)^0 -> 67099.92 | O5: =(ASSUMPTIONS!$B$13+ASSUMPTIONS!$B$14)*12*(1+ASSUMPTIONS!$B$52)^0 -> 38623.92 | P5: =MAX((N5-O5)*(ASSUMPTIONS!$C$64+ASSUMPTIONS!$C$67),0) -> 5410.44 | Q5: 0 | R5: =ASSUMPTIONS!$B$70*12*(1+ASSUMPTIONS!$B$71)^0 -> 28725.84 | S5: =ASSUMPTIONS!$C$60*12 -> 22800 | T5: =N5+O5-P5-Q5-R5-S5 -> 48787.56 | U5: =ASSUMPTIONS!$C$58*(1+ASSUMPTIONS!$C$59)+S5+MAX(T5,0)*0.2 -> 228367.51 | V5: Active Duty | W5: =ASSUMPTIONS!$B$12*12*(1+ASSUMPTIONS!$B$52)^0 -> 67099.92 | X5: =(ASSUMPTIONS!$B$13+ASSUMPTIONS!$B$14)*12*(1+ASSUMPTIONS!$B$52)^0 -> 38623.92 | Y5: =MAX((W5-X5)*(ASSUMPTIONS!$D$64+ASSUMPTIONS!$D$67),0) -> 5410.44 | Z5: 0 | AA5: =ASSUMPTIONS!$B$70*12*(1+ASSUMPTIONS!$B$71)^0 -> 28725.84 | AB5: =ASSUMPTIONS!$D$60*12 -> 22800 | AC5: =W5+X5-Y5-Z5-AA5-AB5 -> 48787.56 | AD5: =ASSUMPTIONS!$D$58*(1+ASSUMPTIONS!$D$59)+AB5+MAX(AC5,0)*0.2 -> 228367.51 | AE5: =(E5+F5)-(N5+O5) -> 0 | AF5: =(E5+F5)-(W5+X5) -> 0 | AG5: =L5-U5 -> 0 | AH5: =L5-AD5 -> 0
A6: 1 | B6: 2027 | C6: 37 | D6: Active Duty | E6: =ASSUMPTIONS!$B$12*12*(1+ASSUMPTIONS!$B$52)^1 -> 68777.418 | F6: =(ASSUMPTIONS!$B$13+ASSUMPTIONS!$B$14)*12*(1+ASSUMPTIONS!$B$52)^1 -> 39589.518 | G6: =MAX((E6-F6)*(ASSUMPTIONS!$B$64+ASSUMPTIONS!$B$67),0) -> 5545.701 | H6: 0 | I6: =ASSUMPTIONS!$B$70*12*(1+ASSUMPTIONS!$B$71)^1 -> 29587.615 | J6: =ASSUMPTIONS!$B$60*12 -> 22800 | K6: =E6+F6-G6-H6-I6-J6 -> 50433.62 | L6: =L5*(1+ASSUMPTIONS!$B$59)+J6+MAX(K6,0)*0.2 -> 277239.96 | M6: Active Duty | N6: =ASSUMPTIONS!$B$12*12*(1+ASSUMPTIONS!$B$52)^1 -> 68777.418 | O6: =(ASSUMPTIONS!$B$13+ASSUMPTIONS!$B$14)*12*(1+ASSUMPTIONS!$B$52)^1 -> 39589.518 | P6: =MAX((N6-O6)*(ASSUMPTIONS!$C$64+ASSUMPTIONS!$C$67),0) -> 5545.701 | Q6: 0 | R6: =ASSUMPTIONS!$B$70*12*(1+ASSUMPTIONS!$B$71)^1 -> 29587.615 | S6: =ASSUMPTIONS!$C$60*12 -> 22800 | T6: =N6+O6-P6-Q6-R6-S6 -> 50433.62 | U6: =U5*(1+ASSUMPTIONS!$C$59)+S6+MAX(T6,0)*0.2 -> 277239.96 | V6: Active Duty | W6: =ASSUMPTIONS!$B$12*12*(1+ASSUMPTIONS!$B$52)^1 -> 68777.418 | X6: =(ASSUMPTIONS!$B$13+ASSUMPTIONS!$B$14)*12*(1+ASSUMPTIONS!$B$52)^1 -> 39589.518 | Y6: =MAX((W6-X6)*(ASSUMPTIONS!$D$64+ASSUMPTIONS!$D$67),0) -> 5545.701 | Z6: 0 | AA6: =ASSUMPTIONS!$B$70*12*(1+ASSUMPTIONS!$B$71)^1 -> 29587.615 | AB6: =ASSUMPTIONS!$D$60*12 -> 22800 | AC6: =W6+X6-Y6-Z6-AA6-AB6 -> 50433.62 | AD6: =AD5*(1+ASSUMPTIONS!$D$59)+AB6+MAX(AC6,0)*0.2 -> 277239.96 | AE6: =(E6+F6)-(N6+O6) -> 0 | AF6: =(E6+F6)-(W6+X6) -> 0 | AG6: =L6-U6 -> 0 | AH6: =L6-AD6 -> 0
A7: 2 | B7: 2028 | C7: 38 | D7: Active Duty | E7: =ASSUMPTIONS!$B$12*12*(1+ASSUMPTIONS!$B$52)^2 -> 70496.853 | F7: =(ASSUMPTIONS!$B$13+ASSUMPTIONS!$B$14)*12*(1+ASSUMPTIONS!$B$52)^2 -> 40579.256 | G7: =MAX((E7-F7)*(ASSUMPTIONS!$B$64+ASSUMPTIONS!$B$67),0) -> 5684.3435 | H7: 0 | I7: =ASSUMPTIONS!$B$70*12*(1+ASSUMPTIONS!$B$71)^2 -> 30475.244 | J7: =ASSUMPTIONS!$B$60*12 -> 22800 | K7: =E7+F7-G7-H7-I7-J7 -> 52116.522 | L7: =L6*(1+ASSUMPTIONS!$B$59)+J7+MAX(K7,0)*0.2 -> 329870.06 | M7: CS / Tech Job | N7: =ASSUMPTIONS!$C$47*(1+ASSUMPTIONS!$B$51)^0 -> 175000 | O7: =ASSUMPTIONS!$C$33*(1+ASSUMPTIONS!$C$34)^0*12 -> 6629.64 | P7: =MAX((N7-O7)*(ASSUMPTIONS!$C$65+ASSUMPTIONS!$C$67),0) -> 48827.404 | Q7: =ASSUMPTIONS!$C$28*(1+ASSUMPTIONS!$C$29)^0 -> 3000 | R7: =ASSUMPTIONS!$B$70*12*(1+ASSUMPTIONS!$B$71)^2 -> 30475.244 | S7: =ASSUMPTIONS!$C$61*12 -> 6000 | T7: =N7+O7-P7-Q7-R7-S7 -> 93326.992 | U7: =U6*(1+ASSUMPTIONS!$C$59)+S7+MAX(T7,0)*0.2 -> 321312.16 | V7: Gap Year | W7: 0 | X7: =ASSUMPTIONS!$D$33*12 -> 6629.64 | Y7: 0 | Z7: =ASSUMPTIONS!$D$30 -> 3000 | AA7: =ASSUMPTIONS!$B$70*12*(1+ASSUMPTIONS!$B$71)^2 -> 30475.244 | AB7: =ASSUMPTIONS!$D$62*12 -> 0 | AC7: =W7+X7-Y7-Z7-AA7-AB7 -> -26845.604 | AD7: =AD6*(1+ASSUMPTIONS!$D$59)+AB7+MAX(AC7,0)*0.2 -> 296646.76 | AE7: =(E7+F7)-(N7+O7) -> -70553.531 | AF7: =(E7+F7)-(W7+X7) -> 104446.47 | AG7: =L7-U7 -> 8557.9061 | AH7: =L7-AD7 -> 33223.304
A8: 3 | B8: 2029 | C8: 39 | D8: Active Duty | E8: =ASSUMPTIONS!$B$12*12*(1+ASSUMPTIONS!$B$52)^3 -> 72259.275 | F8: =(ASSUMPTIONS!$B$13+ASSUMPTIONS!$B$14)*12*(1+ASSUMPTIONS!$B$52)^3 -> 41593.737 | G8: =MAX((E8-F8)*(ASSUMPTIONS!$B$64+ASSUMPTIONS!$B$67),0) -> 5826.4521 | H8: 0 | I8: =ASSUMPTIONS!$B$70*12*(1+ASSUMPTIONS!$B$71)^3 -> 31389.501 | J8: =ASSUMPTIONS!$B$60*12 -> 22800 | K8: =E8+F8-G8-H8-I8-J8 -> 53837.059 | L8: =L7*(1+ASSUMPTIONS!$B$59)+J8+MAX(K8,0)*0.2 -> 386528.38 | M8: CS / Tech Job | N8: =ASSUMPTIONS!$C$47*(1+ASSUMPTIONS!$B$51)^1 -> 182000 | O8: =ASSUMPTIONS!$C$33*(1+ASSUMPTIONS!$C$34)^1*12 -> 6815.2699 | P8: =MAX((N8-O8)*(ASSUMPTIONS!$C$65+ASSUMPTIONS!$C$67),0) -> 50803.572 | Q8: =ASSUMPTIONS!$C$28*(1+ASSUMPTIONS!$C$29)^1 -> 3240 | R8: =ASSUMPTIONS!$B$70*12*(1+ASSUMPTIONS!$B$71)^3 -> 31389.501 | S8: =ASSUMPTIONS!$C$61*12 -> 6000 | T8: =N8+O8-P8-Q8-R8-S8 -> 97382.197 | U8: =U7*(1+ASSUMPTIONS!$C$59)+S8+MAX(T8,0)*0.2 -> 369280.45 | V8: PhD Student | W8: =ASSUMPTIONS!$D$46 -> 47000 | X8: =ASSUMPTIONS!$D$33*(1+ASSUMPTIONS!$D$34)^1*12+ASSUMPTIONS!$D$38*12+ASSUMPTIONS!$D$39 -> 67719.27 | Y8: =MAX(W8*0.1,0) -> 4700 | Z8: 0 | AA8: =ASSUMPTIONS!$B$70*12*(1+ASSUMPTIONS!$B$71)^3 -> 31389.501 | AB8: =ASSUMPTIONS!$D$62*12 -> 0 | AC8: =W8+X8-Y8-Z8-AA8-AB8 -> 78629.769 | AD8: =AD7*(1+ASSUMPTIONS!$D$59)+AB8+MAX(AC8,0)*0.2 -> 333137.99 | AE8: =(E8+F8)-(N8+O8) -> -74962.258 | AF8: =(E8+F8)-(W8+X8) -> -866.25779 | AG8: =L8-U8 -> 17247.932 | AH8: =L8-AD8 -> 53390.394
A9: 4 | B9: 2030 | C9: 40 | D9: Active Duty | E9: =ASSUMPTIONS!$B$12*12*(1+ASSUMPTIONS!$B$52)^4 -> 74065.757 | F9: =(ASSUMPTIONS!$B$13+ASSUMPTIONS!$B$14)*12*(1+ASSUMPTIONS!$B$52)^4 -> 42633.581 | G9: =MAX((E9-F9)*(ASSUMPTIONS!$B$64+ASSUMPTIONS!$B$67),0) -> 5972.1134 | H9: 0 | I9: =ASSUMPTIONS!$B$70*12*(1+ASSUMPTIONS!$B$71)^4 -> 32331.186 | J9: =ASSUMPTIONS!$B$60*12 -> 22800 | K9: =E9+F9-G9-H9-I9-J9 -> 55596.038 | L9: =L8*(1+ASSUMPTIONS!$B$59)+J9+MAX(K9,0)*0.2 -> 447504.57 | M9: CS / Tech Job | N9: =ASSUMPTIONS!$C$47*(1+ASSUMPTIONS!$B$51)^2 -> 189280 | O9: =ASSUMPTIONS!$C$33*(1+ASSUMPTIONS!$C$34)^2*12 -> 7006.0975 | P9: =MAX((N9-O9)*(ASSUMPTIONS!$C$65+ASSUMPTIONS!$C$67),0) -> 52859.432 | Q9: =ASSUMPTIONS!$C$28*(1+ASSUMPTIONS!$C$29)^2 -> 3499.2 | R9: =ASSUMPTIONS!$B$70*12*(1+ASSUMPTIONS!$B$71)^4 -> 32331.186 | S9: =ASSUMPTIONS!$C$61*12 -> 6000 | T9: =N9+O9-P9-Q9-R9-S9 -> 101596.28 | U9: =U8*(1+ASSUMPTIONS!$C$59)+S9+MAX(T9,0)*0.2 -> 421449.34 | V9: PhD Student | W9: =ASSUMPTIONS!$D$46 -> 47000 | X9: =ASSUMPTIONS!$D$33*(1+ASSUMPTIONS!$D$34)^2*12+ASSUMPTIONS!$D$38*12+ASSUMPTIONS!$D$39 -> 67910.097 | Y9: =MAX(W9*0.1,0) -> 4700 | Z9: 0 | AA9: =ASSUMPTIONS!$B$70*12*(1+ASSUMPTIONS!$B$71)^4 -> 32331.186 | AB9: =ASSUMPTIONS!$D$62*12 -> 0 | AC9: =W9+X9-Y9-Z9-AA9-AB9 -> 77878.911 | AD9: =AD8*(1+ASSUMPTIONS!$D$59)+AB9+MAX(AC9,0)*0.2 -> 372033.43 | AE9: =(E9+F9)-(N9+O9) -> -79586.76 | AF9: =(E9+F9)-(W9+X9) -> 1789.24 | AG9: =L9-U9 -> 26055.239 | AH9: =L9-AD9 -> 75471.147
A10: 5 | B10: 2031 | C10: 41 | D10: Active Duty | E10: =ASSUMPTIONS!$B$12*12*(1+ASSUMPTIONS!$B$52)^5 -> 75917.401 | F10: =(ASSUMPTIONS!$B$13+ASSUMPTIONS!$B$14)*12*(1+ASSUMPTIONS!$B$52)^5 -> 43699.42 | G10: =MAX((E10-F10)*(ASSUMPTIONS!$B$64+ASSUMPTIONS!$B$67),0) -> 6121.4163 | H10: 0 | I10: =ASSUMPTIONS!$B$70*12*(1+ASSUMPTIONS!$B$71)^5 -> 33301.122 | J10: =ASSUMPTIONS!$B$60*12 -> 22800 | K10: =E10+F10-G10-H10-I10-J10 -> 57394.283 | L10: =L9*(1+ASSUMPTIONS!$B$59)+J10+MAX(K10,0)*0.2 -> 513108.75 | M10: CS / Tech Job | N10: =ASSUMPTIONS!$C$47*(1+ASSUMPTIONS!$B$51)^3 -> 196851.2 | O10: =ASSUMPTIONS!$C$33*(1+ASSUMPTIONS!$C$34)^3*12 -> 7202.2682 | P10: =MAX((N10-O10)*(ASSUMPTIONS!$C$65+ASSUMPTIONS!$C$67),0) -> 54998.19 | Q10: =ASSUMPTIONS!$C$28*(1+ASSUMPTIONS!$C$29)^3 -> 3779.136 | R10: =ASSUMPTIONS!$B$70*12*(1+ASSUMPTIONS!$B$71)^5 -> 33301.122 | S10: =ASSUMPTIONS!$C$61*12 -> 6000 | T10: =N10+O10-P10-Q10-R10-S10 -> 105975.02 | U10: =U9*(1+ASSUMPTIONS!$C$59)+S10+MAX(T10,0)*0.2 -> 478145.79 | V10: PhD Student | W10: =ASSUMPTIONS!$D$46 -> 47000 | X10: =ASSUMPTIONS!$D$33*(1+ASSUMPTIONS!$D$34)^3*12+ASSUMPTIONS!$D$38*12+ASSUMPTIONS!$D$39 -> 68106.268 | Y10: =MAX(W10*0.1,0) -> 4700 | Z10: 0 | AA10: =ASSUMPTIONS!$B$70*12*(1+ASSUMPTIONS!$B$71)^5 -> 33301.122 | AB10: =ASSUMPTIONS!$D$62*12 -> 0 | AC10: =W10+X10-Y10-Z10-AA10-AB10 -> 77105.147 | AD10: =AD9*(1+ASSUMPTIONS!$D$59)+AB10+MAX(AC10,0)*0.2 -> 413496.8 | AE10: =(E10+F10)-(N10+O10) -> -84436.647 | AF10: =(E10+F10)-(W10+X10) -> 4510.5527 | AG10: =L10-U10 -> 34962.958 | AH10: =L10-AD10 -> 99611.954
A11: 6 | B11: 2032 | C11: 42 | D11: Active Duty | E11: =ASSUMPTIONS!$B$12*12*(1+ASSUMPTIONS!$B$52)^6 -> 77815.336 | F11: =(ASSUMPTIONS!$B$13+ASSUMPTIONS!$B$14)*12*(1+ASSUMPTIONS!$B$52)^6 -> 44791.906 | G11: =MAX((E11-F11)*(ASSUMPTIONS!$B$64+ASSUMPTIONS!$B$67),0) -> 6274.4517 | H11: 0 | I11: =ASSUMPTIONS!$B$70*12*(1+ASSUMPTIONS!$B$71)^6 -> 34300.155 | J11: =ASSUMPTIONS!$B$60*12 -> 22800 | K11: =E11+F11-G11-H11-I11-J11 -> 59232.635 | L11: =L10*(1+ASSUMPTIONS!$B$59)+J11+MAX(K11,0)*0.2 -> 583672.89 | M11: CS / Tech Job | N11: =ASSUMPTIONS!$C$47*(1+ASSUMPTIONS!$B$51)^4 -> 204725.25 | O11: =ASSUMPTIONS!$C$33*(1+ASSUMPTIONS!$C$34)^4*12 -> 7403.9317 | P11: =MAX((N11-O11)*(ASSUMPTIONS!$C$65+ASSUMPTIONS!$C$67),0) -> 57223.182 | Q11: =ASSUMPTIONS!$C$28*(1+ASSUMPTIONS!$C$29)^4 -> 4081.4669 | R11: =ASSUMPTIONS!$B$70*12*(1+ASSUMPTIONS!$B$71)^6 -> 34300.155 | S11: =ASSUMPTIONS!$C$61*12 -> 6000 | T11: =N11+O11-P11-Q11-R11-S11 -> 110524.38 | U11: =U10*(1+ASSUMPTIONS!$C$59)+S11+MAX(T11,0)*0.2 -> 539720.87 | V11: PhD Student | W11: =ASSUMPTIONS!$D$46 -> 47000 | X11: =ASSUMPTIONS!$D$33*(1+ASSUMPTIONS!$D$34)^4*12+ASSUMPTIONS!$D$38*12+ASSUMPTIONS!$D$39 -> 68307.932 | Y11: =MAX(W11*0.1,0) -> 4700 | Z11: 0 | AA11: =ASSUMPTIONS!$B$70*12*(1+ASSUMPTIONS!$B$71)^6 -> 34300.155 | AB11: =ASSUMPTIONS!$D$62*12 -> 0 | AC11: =W11+X11-Y11-Z11-AA11-AB11 -> 76307.776 | AD11: =AD10*(1+ASSUMPTIONS!$D$59)+AB11+MAX(AC11,0)*0.2 -> 457703.13 | AE11: =(E11+F11)-(N11+O11) -> -89521.938 | AF11: =(E11+F11)-(W11+X11) -> 7299.3097 | AG11: =L11-U11 -> 43952.017 | AH11: =L11-AD11 -> 125969.76
A12: 7 | B12: 2033 | C12: 43 | D12: Active Duty | E12: =ASSUMPTIONS!$B$12*12*(1+ASSUMPTIONS!$B$52)^7 -> 79760.719 | F12: =(ASSUMPTIONS!$B$13+ASSUMPTIONS!$B$14)*12*(1+ASSUMPTIONS!$B$52)^7 -> 45911.703 | G12: =MAX((E12-F12)*(ASSUMPTIONS!$B$64+ASSUMPTIONS!$B$67),0) -> 6431.3129 | H12: 0 | I12: =ASSUMPTIONS!$B$70*12*(1+ASSUMPTIONS!$B$71)^7 -> 35329.16 | J12: =ASSUMPTIONS!$B$60*12 -> 22800 | K12: =E12+F12-G12-H12-I12-J12 -> 61111.95 | L12: =L11*(1+ASSUMPTIONS!$B$59)+J12+MAX(K12,0)*0.2 -> 659552.38 | M12: CS / Tech Job | N12: =ASSUMPTIONS!$C$47*(1+ASSUMPTIONS!$B$51)^5 -> 212914.26 | O12: =ASSUMPTIONS!$C$33*(1+ASSUMPTIONS!$C$34)^5*12 -> 7611.2418 | P12: =MAX((N12-O12)*(ASSUMPTIONS!$C$65+ASSUMPTIONS!$C$67),0) -> 59537.875 | Q12: =ASSUMPTIONS!$C$28*(1+ASSUMPTIONS!$C$29)^5 -> 4407.9842 | R12: =ASSUMPTIONS!$B$70*12*(1+ASSUMPTIONS!$B$71)^7 -> 35329.16 | S12: =ASSUMPTIONS!$C$61*12 -> 6000 | T12: =N12+O12-P12-Q12-R12-S12 -> 115250.48 | U12: =U11*(1+ASSUMPTIONS!$C$59)+S12+MAX(T12,0)*0.2 -> 606551.43 | V12: PhD Student | W12: =ASSUMPTIONS!$D$46 -> 47000 | X12: =ASSUMPTIONS!$D$33*(1+ASSUMPTIONS!$D$34)^5*12+ASSUMPTIONS!$D$38*12+ASSUMPTIONS!$D$39 -> 68515.242 | Y12: =MAX(W12*0.1,0) -> 4700 | Z12: 0 | AA12: =ASSUMPTIONS!$B$70*12*(1+ASSUMPTIONS!$B$71)^7 -> 35329.16 | AB12: =ASSUMPTIONS!$D$62*12 -> 0 | AC12: =W12+X12-Y12-Z12-AA12-AB12 -> 75486.082 | AD12: =AD11*(1+ASSUMPTIONS!$D$59)+AB12+MAX(AC12,0)*0.2 -> 504839.56 | AE12: =(E12+F12)-(N12+O12) -> -94853.077 | AF12: =(E12+F12)-(W12+X12) -> 10157.181 | AG12: =L12-U12 -> 53000.952 | AH12: =L12-AD12 -> 154712.82
A13: 8 | B13: 2034 | C13: 44 | D13: Retirement Year | E13: =ASSUMPTIONS!$B$12*12*(1+ASSUMPTIONS!$B$52)^8*0.75+ASSUMPTIONS!$B$21*12*0.25 -> 72215.053 | F13: =(ASSUMPTIONS!$B$13+ASSUMPTIONS!$B$14)*12*(1+ASSUMPTIONS!$B$52)^8*0.75+ASSUMPTIONS!$B$33*12*0.25 -> 36952.032 | G13: =MAX((E13-F13)*(ASSUMPTIONS!$B$64+ASSUMPTIONS!$B$67),0) -> 6699.9739 | H13: =ASSUMPTIONS!$B$26*0.25 -> 45.5 | I13: =ASSUMPTIONS!$B$70*12*(1+ASSUMPTIONS!$B$71)^8 -> 36389.035 | J13: =ASSUMPTIONS!$B$62*12 -> 0 | K13: =E13+F13-G13-H13-I13-J13 -> 66032.576 | L13: =L12*(1+ASSUMPTIONS!$B$59)+J13+MAX(K13,0)*0.2 -> 718927.56 | M13: CS / Tech Job | N13: =ASSUMPTIONS!$C$47*(1+ASSUMPTIONS!$B$51)^6 -> 221430.83 | O13: =ASSUMPTIONS!$C$33*(1+ASSUMPTIONS!$C$34)^6*12 -> 7824.3566 | P13: =MAX((N13-O13)*(ASSUMPTIONS!$C$65+ASSUMPTIONS!$C$67),0) -> 61945.877 | Q13: =ASSUMPTIONS!$C$28*(1+ASSUMPTIONS!$C$29)^6 -> 4760.623 | R13: =ASSUMPTIONS!$B$70*12*(1+ASSUMPTIONS!$B$71)^8 -> 36389.035 | S13: =ASSUMPTIONS!$C$61*12 -> 6000 | T13: =N13+O13-P13-Q13-R13-S13 -> 120159.65 | U13: =U12*(1+ASSUMPTIONS!$C$59)+S13+MAX(T13,0)*0.2 -> 679041.96 | V13: Research Scientist | W13: =ASSUMPTIONS!$D$48*(1+ASSUMPTIONS!$B$51)^0 -> 230000 | X13: =ASSUMPTIONS!$D$33*(1+ASSUMPTIONS!$D$34)^6*12 -> 7824.3566 | Y13: =MAX((W13-X13)*(ASSUMPTIONS!$D$66+ASSUMPTIONS!$D$67),0) -> 68874.449 | Z13: =ASSUMPTIONS!$D$28*(1+ASSUMPTIONS!$D$29)^6 -> 0 | AA13: =ASSUMPTIONS!$B$70*12*(1+ASSUMPTIONS!$B$71)^8 -> 36389.035 | AB13: =ASSUMPTIONS!$D$61*12 -> 6000 | AC13: =W13+X13-Y13-Z13-AA13-AB13 -> 126560.87 | AD13: =AD12*(1+ASSUMPTIONS!$D$59)+AB13+MAX(AC13,0)*0.2 -> 571490.51 | AE13: =(E13+F13)-(N13+O13) -> -120088.1 | AF13: =(E13+F13)-(W13+X13) -> -128657.27 | AG13: =L13-U13 -> 39885.603 | AH13: =L13-AD13 -> 147437.06
A14: 9 | B14: 2035 | C14: 45 | D14: PhD Student | E14: =ASSUMPTIONS!$B$21*(1+ASSUMPTIONS!$B$23)^1*12+ASSUMPTIONS!$B$46 -> 91816.688 | F14: =ASSUMPTIONS!$B$33*(1+ASSUMPTIONS!$B$34)^1*12+ASSUMPTIONS!$B$38*12+ASSUMPTIONS!$B$39 -> 67719.27 | G14: =MAX((E14-F14)*(ASSUMPTIONS!$B$64+ASSUMPTIONS!$B$67),0) -> 4578.5094 | H14: =ASSUMPTIONS!$B$26*(1+ASSUMPTIONS!$B$27)^1 -> 187.46 | I14: =ASSUMPTIONS!$B$70*12*(1+ASSUMPTIONS!$B$71)^9 -> 37480.706 | J14: =ASSUMPTIONS!$B$62*12 -> 0 | K14: =E14+F14-G14-H14-I14-J14 -> 117289.28 | L14: =L13*(1+ASSUMPTIONS!$B$59)+J14+MAX(K14,0)*0.2 -> 792710.35 | M14: CS / Tech Job | N14: =ASSUMPTIONS!$C$47*(1+ASSUMPTIONS!$B$51)^7 -> 230288.06 | O14: =ASSUMPTIONS!$C$33*(1+ASSUMPTIONS!$C$34)^7*12 -> 8043.4386 | P14: =MAX((N14-O14)*(ASSUMPTIONS!$C$65+ASSUMPTIONS!$C$67),0) -> 64450.941 | Q14: =ASSUMPTIONS!$C$28*(1+ASSUMPTIONS!$C$29)^7 -> 5141.4728 | R14: =ASSUMPTIONS!$B$70*12*(1+ASSUMPTIONS!$B$71)^9 -> 37480.706 | S14: =ASSUMPTIONS!$C$61*12 -> 6000 | T14: =N14+O14-P14-Q14-R14-S14 -> 125258.38 | U14: =U13*(1+ASSUMPTIONS!$C$59)+S14+MAX(T14,0)*0.2 -> 757626.57 | V14: Research Scientist | W14: =ASSUMPTIONS!$D$48*(1+ASSUMPTIONS!$B$51)^1 -> 239200 | X14: =ASSUMPTIONS!$D$33*(1+ASSUMPTIONS!$D$34)^7*12 -> 8043.4386 | Y14: =MAX((W14-X14)*(ASSUMPTIONS!$D$66+ASSUMPTIONS!$D$67),0) -> 71658.534 | Z14: =ASSUMPTIONS!$D$28*(1+ASSUMPTIONS!$D$29)^7 -> 0 | AA14: =ASSUMPTIONS!$B$70*12*(1+ASSUMPTIONS!$B$71)^9 -> 37480.706 | AB14: =ASSUMPTIONS!$D$61*12 -> 6000 | AC14: =W14+X14-Y14-Z14-AA14-AB14 -> 132104.2 | AD14: =AD13*(1+ASSUMPTIONS!$D$59)+AB14+MAX(AC14,0)*0.2 -> 643915.68 | AE14: =(E14+F14)-(N14+O14) -> -78795.542 | AF14: =(E14+F14)-(W14+X14) -> -87707.481 | AG14: =L14-U14 -> 35083.776 | AH14: =L14-AD14 -> 148794.67
A15: 10 | B15: 2036 | C15: 46 | D15: PhD Student | E15: =ASSUMPTIONS!$B$21*(1+ASSUMPTIONS!$B$23)^2*12+ASSUMPTIONS!$B$46 -> 93071.555 | F15: =ASSUMPTIONS!$B$33*(1+ASSUMPTIONS!$B$34)^2*12+ASSUMPTIONS!$B$38*12+ASSUMPTIONS!$B$39 -> 67910.097 | G15: =MAX((E15-F15)*(ASSUMPTIONS!$B$64+ASSUMPTIONS!$B$67),0) -> 4780.677 | H15: =ASSUMPTIONS!$B$26*(1+ASSUMPTIONS!$B$27)^2 -> 193.0838 | I15: =ASSUMPTIONS!$B$70*12*(1+ASSUMPTIONS!$B$71)^10 -> 38605.127 | J15: =ASSUMPTIONS!$B$62*12 -> 0 | K15: =E15+F15-G15-H15-I15-J15 -> 117402.77 | L15: =L14*(1+ASSUMPTIONS!$B$59)+J15+MAX(K15,0)*0.2 -> 871680.63 | M15: CS / Tech Job | N15: =ASSUMPTIONS!$C$47*(1+ASSUMPTIONS!$B$51)^8 -> 239499.58 | O15: =ASSUMPTIONS!$C$33*(1+ASSUMPTIONS!$C$34)^8*12 -> 8268.6548 | P15: =MAX((N15-O15)*(ASSUMPTIONS!$C$65+ASSUMPTIONS!$C$67),0) -> 67056.969 | Q15: =ASSUMPTIONS!$C$28*(1+ASSUMPTIONS!$C$29)^8 -> 5552.7906 | R15: =ASSUMPTIONS!$B$70*12*(1+ASSUMPTIONS!$B$71)^10 -> 38605.127 | S15: =ASSUMPTIONS!$C$61*12 -> 6000 | T15: =N15+O15-P15-Q15-R15-S15 -> 130553.35 | U15: =U14*(1+ASSUMPTIONS!$C$59)+S15+MAX(T15,0)*0.2 -> 842771.11 | V15: Research Scientist | W15: =ASSUMPTIONS!$D$48*(1+ASSUMPTIONS!$B$51)^2 -> 248768 | X15: =ASSUMPTIONS!$D$33*(1+ASSUMPTIONS!$D$34)^8*12 -> 8268.6548 | Y15: =MAX((W15-X15)*(ASSUMPTIONS!$D$66+ASSUMPTIONS!$D$67),0) -> 74554.797 | Z15: =ASSUMPTIONS!$D$28*(1+ASSUMPTIONS!$D$29)^8 -> 0 | AA15: =ASSUMPTIONS!$B$70*12*(1+ASSUMPTIONS!$B$71)^10 -> 38605.127 | AB15: =ASSUMPTIONS!$D$61*12 -> 6000 | AC15: =W15+X15-Y15-Z15-AA15-AB15 -> 137876.73 | AD15: =AD14*(1+ASSUMPTIONS!$D$59)+AB15+MAX(AC15,0)*0.2 -> 722565.13 | AE15: =(E15+F15)-(N15+O15) -> -86786.586 | AF15: =(E15+F15)-(W15+X15) -> -96055.002 | AG15: =L15-U15 -> 28909.523 | AH15: =L15-AD15 -> 149115.5
A16: 11 | B16: 2037 | C16: 47 | D16: PhD Student | E16: =ASSUMPTIONS!$B$21*(1+ASSUMPTIONS!$B$23)^3*12+ASSUMPTIONS!$B$46 -> 94361.559 | F16: =ASSUMPTIONS!$B$33*(1+ASSUMPTIONS!$B$34)^3*12+ASSUMPTIONS!$B$38*12+ASSUMPTIONS!$B$39 -> 68106.268 | G16: =MAX((E16-F16)*(ASSUMPTIONS!$B$64+ASSUMPTIONS!$B$67),0) -> 4988.5052 | H16: =ASSUMPTIONS!$B$26*(1+ASSUMPTIONS!$B$27)^3 -> 198.87631 | I16: =ASSUMPTIONS!$B$70*12*(1+ASSUMPTIONS!$B$71)^11 -> 39763.281 | J16: =ASSUMPTIONS!$B$62*12 -> 0 | K16: =E16+F16-G16-H16-I16-J16 -> 117517.16 | L16: =L15*(1+ASSUMPTIONS!$B$59)+J16+MAX(K16,0)*0.2 -> 956201.71 | M16: CS / Tech Job | N16: =ASSUMPTIONS!$C$47*(1+ASSUMPTIONS!$B$51)^9 -> 249079.57 | O16: =ASSUMPTIONS!$C$33*(1+ASSUMPTIONS!$C$34)^9*12 -> 8500.1772 | P16: =MAX((N16-O16)*(ASSUMPTIONS!$C$65+ASSUMPTIONS!$C$67),0) -> 69768.023 | Q16: =ASSUMPTIONS!$C$28*(1+ASSUMPTIONS!$C$29)^9 -> 5997.0139 | R16: =ASSUMPTIONS!$B$70*12*(1+ASSUMPTIONS!$B$71)^11 -> 39763.281 | S16: =ASSUMPTIONS!$C$61*12 -> 6000 | T16: =N16+O16-P16-Q16-R16-S16 -> 136051.43 | U16: =U15*(1+ASSUMPTIONS!$C$59)+S16+MAX(T16,0)*0.2 -> 934975.37 | V16: Research Scientist | W16: =ASSUMPTIONS!$D$48*(1+ASSUMPTIONS!$B$51)^3 -> 258718.72 | X16: =ASSUMPTIONS!$D$33*(1+ASSUMPTIONS!$D$34)^9*12 -> 8500.1772 | Y16: =MAX((W16-X16)*(ASSUMPTIONS!$D$66+ASSUMPTIONS!$D$67),0) -> 77567.748 | Z16: =ASSUMPTIONS!$D$28*(1+ASSUMPTIONS!$D$29)^9 -> 0 | AA16: =ASSUMPTIONS!$B$70*12*(1+ASSUMPTIONS!$B$71)^11 -> 39763.281 | AB16: =ASSUMPTIONS!$D$61*12 -> 6000 | AC16: =W16+X16-Y16-Z16-AA16-AB16 -> 143887.87 | AD16: =AD15*(1+ASSUMPTIONS!$D$59)+AB16+MAX(AC16,0)*0.2 -> 807922.26 | AE16: =(E16+F16)-(N16+O16) -> -95111.917 | AF16: =(E16+F16)-(W16+X16) -> -104751.07 | AG16: =L16-U16 -> 21226.337 | AH16: =L16-AD16 -> 148279.45
A17: 12 | B17: 2038 | C17: 48 | D17: PhD Student | E17: =ASSUMPTIONS!$B$21*(1+ASSUMPTIONS!$B$23)^4*12+ASSUMPTIONS!$B$46 -> 95687.682 | F17: =ASSUMPTIONS!$B$33*(1+ASSUMPTIONS!$B$34)^4*12+ASSUMPTIONS!$B$38*12+ASSUMPTIONS!$B$39 -> 68307.932 | G17: =MAX((E17-F17)*(ASSUMPTIONS!$B$64+ASSUMPTIONS!$B$67),0) -> 5202.1526 | H17: =ASSUMPTIONS!$B$26*(1+ASSUMPTIONS!$B$27)^4 -> 204.8426 | I17: =ASSUMPTIONS!$B$70*12*(1+ASSUMPTIONS!$B$71)^12 -> 40956.179 | J17: =ASSUMPTIONS!$B$62*12 -> 0 | K17: =E17+F17-G17-H17-I17-J17 -> 117632.44 | L17: =L16*(1+ASSUMPTIONS!$B$59)+J17+MAX(K17,0)*0.2 -> 1046662.3 | M17: CS / Tech Job | N17: =ASSUMPTIONS!$C$47*(1+ASSUMPTIONS!$B$51)^10 -> 259042.75 | O17: =ASSUMPTIONS!$C$33*(1+ASSUMPTIONS!$C$34)^10*12 -> 8738.1821 | P17: =MAX((N17-O17)*(ASSUMPTIONS!$C$65+ASSUMPTIONS!$C$67),0) -> 72588.325 | Q17: =ASSUMPTIONS!$C$28*(1+ASSUMPTIONS!$C$29)^10 -> 6476.775 | R17: =ASSUMPTIONS!$B$70*12*(1+ASSUMPTIONS!$B$71)^12 -> 40956.179 | S17: =ASSUMPTIONS!$C$61*12 -> 6000 | T17: =N17+O17-P17-Q17-R17-S17 -> 141759.65 | U17: =U16*(1+ASSUMPTIONS!$C$59)+S17+MAX(T17,0)*0.2 -> 1034775.6 | V17: Research Scientist | W17: =ASSUMPTIONS!$D$48*(1+ASSUMPTIONS!$B$51)^4 -> 269067.47 | X17: =ASSUMPTIONS!$D$33*(1+ASSUMPTIONS!$D$34)^10*12 -> 8738.1821 | Y17: =MAX((W17-X17)*(ASSUMPTIONS!$D$66+ASSUMPTIONS!$D$67),0) -> 80702.079 | Z17: =ASSUMPTIONS!$D$28*(1+ASSUMPTIONS!$D$29)^10 -> 0 | AA17: =ASSUMPTIONS!$B$70*12*(1+ASSUMPTIONS!$B$71)^12 -> 40956.179 | AB17: =ASSUMPTIONS!$D$61*12 -> 6000 | AC17: =W17+X17-Y17-Z17-AA17-AB17 -> 150147.39 | AD17: =AD16*(1+ASSUMPTIONS!$D$59)+AB17+MAX(AC17,0)*0.2 -> 900506.3 | AE17: =(E17+F17)-(N17+O17) -> -103785.32 | AF17: =(E17+F17)-(W17+X17) -> -113810.04 | AG17: =L17-U17 -> 11886.738 | AH17: =L17-AD17 -> 146156.02
A18: 13 | B18: 2039 | C18: 49 | D18: PhD Student | E18: =ASSUMPTIONS!$B$21*(1+ASSUMPTIONS!$B$23)^5*12+ASSUMPTIONS!$B$46 -> 97050.938 | F18: =ASSUMPTIONS!$B$33*(1+ASSUMPTIONS!$B$34)^5*12+ASSUMPTIONS!$B$38*12+ASSUMPTIONS!$B$39 -> 68515.242 | G18: =MAX((E18-F18)*(ASSUMPTIONS!$B$64+ASSUMPTIONS!$B$67),0) -> 5421.7822 | H18: =ASSUMPTIONS!$B$26*(1+ASSUMPTIONS!$B$27)^5 -> 210.98788 | I18: =ASSUMPTIONS!$B$70*12*(1+ASSUMPTIONS!$B$71)^13 -> 42184.864 | J18: =ASSUMPTIONS!$B$62*12 -> 0 | K18: =E18+F18-G18-H18-I18-J18 -> 117748.54 | L18: =L17*(1+ASSUMPTIONS!$B$59)+J18+MAX(K18,0)*0.2 -> 1143478.4 | M18: CS / Tech Job | N18: =ASSUMPTIONS!$C$47*(1+ASSUMPTIONS!$B$51)^11 -> 269404.46 | O18: =ASSUMPTIONS!$C$33*(1+ASSUMPTIONS!$C$34)^11*12 -> 8982.8512 | P18: =MAX((N18-O18)*(ASSUMPTIONS!$C$65+ASSUMPTIONS!$C$67),0) -> 75522.266 | Q18: =ASSUMPTIONS!$C$28*(1+ASSUMPTIONS!$C$29)^11 -> 6994.917 | R18: =ASSUMPTIONS!$B$70*12*(1+ASSUMPTIONS!$B$71)^13 -> 42184.864 | S18: =ASSUMPTIONS!$C$61*12 -> 6000 | T18: =N18+O18-P18-Q18-R18-S18 -> 147685.26 | U18: =U17*(1+ASSUMPTIONS!$C$59)+S18+MAX(T18,0)*0.2 -> 1142746.9 | V18: Research Scientist | W18: =ASSUMPTIONS!$D$48*(1+ASSUMPTIONS!$B$51)^5 -> 279830.17 | X18: =ASSUMPTIONS!$D$33*(1+ASSUMPTIONS!$D$34)^11*12 -> 8982.8512 | Y18: =MAX((W18-X18)*(ASSUMPTIONS!$D$66+ASSUMPTIONS!$D$67),0) -> 83962.668 | Z18: =ASSUMPTIONS!$D$28*(1+ASSUMPTIONS!$D$29)^11 -> 0 | AA18: =ASSUMPTIONS!$B$70*12*(1+ASSUMPTIONS!$B$71)^13 -> 42184.864 | AB18: =ASSUMPTIONS!$D$61*12 -> 6000 | AC18: =W18+X18-Y18-Z18-AA18-AB18 -> 156665.49 | AD18: =AD17*(1+ASSUMPTIONS!$D$59)+AB18+MAX(AC18,0)*0.2 -> 1000874.8 | AE18: =(E18+F18)-(N18+O18) -> -112821.13 | AF18: =(E18+F18)-(W18+X18) -> -123246.84 | AG18: =L18-U18 -> 731.46622 | AH18: =L18-AD18 -> 142603.55
A19: 14 | B19: 2040 | C19: 50 | D19: Research Scientist | E19: =ASSUMPTIONS!$B$21*(1+ASSUMPTIONS!$B$23)^6*12+ASSUMPTIONS!$B$48*(1+ASSUMPTIONS!$B$51)^0 -> 281452.36 | F19: =ASSUMPTIONS!$B$33*(1+ASSUMPTIONS!$B$34)^6*12 -> 7824.3566 | G19: =MAX((E19-F19)*(ASSUMPTIONS!$B$66+ASSUMPTIONS!$B$67),0) -> 84824.682 | H19: =ASSUMPTIONS!$B$26*(1+ASSUMPTIONS!$B$27)^6 -> 217.31752 | I19: =ASSUMPTIONS!$B$70*12*(1+ASSUMPTIONS!$B$71)^14 -> 43450.41 | J19: =ASSUMPTIONS!$B$61*12 -> 6000 | K19: =E19+F19-G19-H19-I19-J19 -> 154784.31 | L19: =L18*(1+ASSUMPTIONS!$B$59)+J19+MAX(K19,0)*0.2 -> 1260478.7 | M19: CS / Tech Job | N19: =ASSUMPTIONS!$C$47*(1+ASSUMPTIONS!$B$51)^12 -> 280180.64 | O19: =ASSUMPTIONS!$C$33*(1+ASSUMPTIONS!$C$34)^12*12 -> 9234.3711 | P19: =MAX((N19-O19)*(ASSUMPTIONS!$C$65+ASSUMPTIONS!$C$67),0) -> 78574.417 | Q19: =ASSUMPTIONS!$C$28*(1+ASSUMPTIONS!$C$29)^12 -> 7554.5104 | R19: =ASSUMPTIONS!$B$70*12*(1+ASSUMPTIONS!$B$71)^14 -> 43450.41 | S19: =ASSUMPTIONS!$C$61*12 -> 6000 | T19: =N19+O19-P19-Q19-R19-S19 -> 153835.67 | U19: =U18*(1+ASSUMPTIONS!$C$59)+S19+MAX(T19,0)*0.2 -> 1259506.3 | V19: Research Scientist | W19: =ASSUMPTIONS!$D$48*(1+ASSUMPTIONS!$B$51)^6 -> 291023.37 | X19: =ASSUMPTIONS!$D$33*(1+ASSUMPTIONS!$D$34)^12*12 -> 9234.3711 | Y19: =MAX((W19-X19)*(ASSUMPTIONS!$D$66+ASSUMPTIONS!$D$67),0) -> 87354.591 | Z19: =ASSUMPTIONS!$D$28*(1+ASSUMPTIONS!$D$29)^12 -> 0 | AA19: =ASSUMPTIONS!$B$70*12*(1+ASSUMPTIONS!$B$71)^14 -> 43450.41 | AB19: =ASSUMPTIONS!$D$61*12 -> 6000 | AC19: =W19+X19-Y19-Z19-AA19-AB19 -> 163452.74 | AD19: =AD18*(1+ASSUMPTIONS!$D$59)+AB19+MAX(AC19,0)*0.2 -> 1109626.6 | AE19: =(E19+F19)-(N19+O19) -> -138.28893 | AF19: =(E19+F19)-(W19+X19) -> -10981.025 | AG19: =L19-U19 -> 972.39668 | AH19: =L19-AD19 -> 150852.11
A20: 15 | B20: 2041 | C20: 51 | D20: Research Scientist | E20: =ASSUMPTIONS!$B$21*(1+ASSUMPTIONS!$B$23)^7*12+ASSUMPTIONS!$B$48*(1+ASSUMPTIONS!$B$51)^1 -> 292093.03 | F20: =ASSUMPTIONS!$B$33*(1+ASSUMPTIONS!$B$34)^7*12 -> 8043.4386 | G20: =MAX((E20-F20)*(ASSUMPTIONS!$B$66+ASSUMPTIONS!$B$67),0) -> 88055.373 | H20: =ASSUMPTIONS!$B$26*(1+ASSUMPTIONS!$B$27)^7 -> 223.83704 | I20: =ASSUMPTIONS!$B$70*12*(1+ASSUMPTIONS!$B$71)^15 -> 44753.923 | J20: =ASSUMPTIONS!$B$61*12 -> 6000 | K20: =E20+F20-G20-H20-I20-J20 -> 161103.34 | L20: =L19*(1+ASSUMPTIONS!$B$59)+J20+MAX(K20,0)*0.2 -> 1386932.9 | M20: CS / Tech Job | N20: =ASSUMPTIONS!$C$47*(1+ASSUMPTIONS!$B$51)^13 -> 291387.86 | O20: =ASSUMPTIONS!$C$33*(1+ASSUMPTIONS!$C$34)^13*12 -> 9492.9335 | P20: =MAX((N20-O20)*(ASSUMPTIONS!$C$65+ASSUMPTIONS!$C$67),0) -> 81749.53 | Q20: =ASSUMPTIONS!$C$28*(1+ASSUMPTIONS!$C$29)^13 -> 8158.8712 | R20: =ASSUMPTIONS!$B$70*12*(1+ASSUMPTIONS!$B$71)^15 -> 44753.923 | S20: =ASSUMPTIONS!$C$61*12 -> 6000 | T20: =N20+O20-P20-Q20-R20-S20 -> 160218.47 | U20: =U19*(1+ASSUMPTIONS!$C$59)+S20+MAX(T20,0)*0.2 -> 1385715.5 | V20: Research Scientist | W20: =ASSUMPTIONS!$D$48*(1+ASSUMPTIONS!$B$51)^7 -> 302664.31 | X20: =ASSUMPTIONS!$D$33*(1+ASSUMPTIONS!$D$34)^13*12 -> 9492.9335 | Y20: =MAX((W20-X20)*(ASSUMPTIONS!$D$66+ASSUMPTIONS!$D$67),0) -> 90883.126 | Z20: =ASSUMPTIONS!$D$28*(1+ASSUMPTIONS!$D$29)^13 -> 0 | AA20: =ASSUMPTIONS!$B$70*12*(1+ASSUMPTIONS!$B$71)^15 -> 44753.923 | AB20: =ASSUMPTIONS!$D$61*12 -> 6000 | AC20: =W20+X20-Y20-Z20-AA20-AB20 -> 170520.19 | AD20: =AD19*(1+ASSUMPTIONS!$D$59)+AB20+MAX(AC20,0)*0.2 -> 1227404.5 | AE20: =(E20+F20)-(N20+O20) -> -744.32867 | AF20: =(E20+F20)-(W20+X20) -> -12020.774 | AG20: =L20-U20 -> 1217.4368 | AH20: =L20-AD20 -> 159528.39
A21: 16 | B21: 2042 | C21: 52 | D21: Research Scientist | E21: =ASSUMPTIONS!$B$21*(1+ASSUMPTIONS!$B$23)^8*12+ASSUMPTIONS!$B$48*(1+ASSUMPTIONS!$B$51)^2 -> 303142.03 | F21: =ASSUMPTIONS!$B$33*(1+ASSUMPTIONS!$B$34)^8*12 -> 8268.6548 | G21: =MAX((E21-F21)*(ASSUMPTIONS!$B$66+ASSUMPTIONS!$B$67),0) -> 91410.748 | H21: =ASSUMPTIONS!$B$26*(1+ASSUMPTIONS!$B$27)^8 -> 230.55215 | I21: =ASSUMPTIONS!$B$70*12*(1+ASSUMPTIONS!$B$71)^16 -> 46096.54 | J21: =ASSUMPTIONS!$B$61*12 -> 6000 | K21: =E21+F21-G21-H21-I21-J21 -> 167672.85 | L21: =L20*(1+ASSUMPTIONS!$B$59)+J21+MAX(K21,0)*0.2 -> 1523552.8 | M21: CS / Tech Job | N21: =ASSUMPTIONS!$C$47*(1+ASSUMPTIONS!$B$51)^14 -> 303043.38 | O21: =ASSUMPTIONS!$C$33*(1+ASSUMPTIONS!$C$34)^14*12 -> 9758.7356 | P21: =MAX((N21-O21)*(ASSUMPTIONS!$C$65+ASSUMPTIONS!$C$67),0) -> 85052.546 | Q21: =ASSUMPTIONS!$C$28*(1+ASSUMPTIONS!$C$29)^14 -> 8811.5809 | R21: =ASSUMPTIONS!$B$70*12*(1+ASSUMPTIONS!$B$71)^16 -> 46096.54 | S21: =ASSUMPTIONS!$C$61*12 -> 6000 | T21: =N21+O21-P21-Q21-R21-S21 -> 166841.45 | U21: =U20*(1+ASSUMPTIONS!$C$59)+S21+MAX(T21,0)*0.2 -> 1522083.8 | V21: Research Scientist | W21: =ASSUMPTIONS!$D$48*(1+ASSUMPTIONS!$B$51)^8 -> 314770.88 | X21: =ASSUMPTIONS!$D$33*(1+ASSUMPTIONS!$D$34)^14*12 -> 9758.7356 | Y21: =MAX((W21-X21)*(ASSUMPTIONS!$D$66+ASSUMPTIONS!$D$67),0) -> 94553.765 | Z21: =ASSUMPTIONS!$D$28*(1+ASSUMPTIONS!$D$29)^14 -> 0 | AA21: =ASSUMPTIONS!$B$70*12*(1+ASSUMPTIONS!$B$71)^16 -> 46096.54 | AB21: =ASSUMPTIONS!$D$61*12 -> 6000 | AC21: =W21+X21-Y21-Z21-AA21-AB21 -> 177879.31 | AD21: =AD20*(1+ASSUMPTIONS!$D$59)+AB21+MAX(AC21,0)*0.2 -> 1354898.7 | AE21: =(E21+F21)-(N21+O21) -> -1391.4242 | AF21: =(E21+F21)-(W21+X21) -> -13118.928 | AG21: =L21-U21 -> 1468.938 | AH21: =L21-AD21 -> 168654.08
A22: 17 | B22: 2043 | C22: 53 | D22: Research Scientist | E22: =ASSUMPTIONS!$B$21*(1+ASSUMPTIONS!$B$23)^9*12+ASSUMPTIONS!$B$48*(1+ASSUMPTIONS!$B$51)^3 -> 314615.23 | F22: =ASSUMPTIONS!$B$33*(1+ASSUMPTIONS!$B$34)^9*12 -> 8500.1772 | G22: =MAX((E22-F22)*(ASSUMPTIONS!$B$66+ASSUMPTIONS!$B$67),0) -> 94895.666 | H22: =ASSUMPTIONS!$B$26*(1+ASSUMPTIONS!$B$27)^9 -> 237.46872 | I22: =ASSUMPTIONS!$B$70*12*(1+ASSUMPTIONS!$B$71)^17 -> 47479.437 | J22: =ASSUMPTIONS!$B$61*12 -> 6000 | K22: =E22+F22-G22-H22-I22-J22 -> 174502.83 | L22: =L21*(1+ASSUMPTIONS!$B$59)+J22+MAX(K22,0)*0.2 -> 1671102 | M22: CS / Tech Job | N22: =ASSUMPTIONS!$C$47*(1+ASSUMPTIONS!$B$51)^15 -> 315165.11 | O22: =ASSUMPTIONS!$C$33*(1+ASSUMPTIONS!$C$34)^15*12 -> 10031.98 | P22: =MAX((N22-O22)*(ASSUMPTIONS!$C$65+ASSUMPTIONS!$C$67),0) -> 88488.609 | Q22: =ASSUMPTIONS!$C$28*(1+ASSUMPTIONS!$C$29)^15 -> 9516.5073 | R22: =ASSUMPTIONS!$B$70*12*(1+ASSUMPTIONS!$B$71)^17 -> 47479.437 | S22: =ASSUMPTIONS!$C$61*12 -> 6000 | T22: =N22+O22-P22-Q22-R22-S22 -> 173712.54 | U22: =U21*(1+ASSUMPTIONS!$C$59)+S22+MAX(T22,0)*0.2 -> 1669372.2 | V22: Research Scientist | W22: =ASSUMPTIONS!$D$48*(1+ASSUMPTIONS!$B$51)^9 -> 327361.72 | X22: =ASSUMPTIONS!$D$33*(1+ASSUMPTIONS!$D$34)^15*12 -> 10031.98 | Y22: =MAX((W22-X22)*(ASSUMPTIONS!$D$66+ASSUMPTIONS!$D$67),0) -> 98372.218 | Z22: =ASSUMPTIONS!$D$28*(1+ASSUMPTIONS!$D$29)^15 -> 0 | AA22: =ASSUMPTIONS!$B$70*12*(1+ASSUMPTIONS!$B$71)^17 -> 47479.437 | AB22: =ASSUMPTIONS!$D$61*12 -> 6000 | AC22: =W22+X22-Y22-Z22-AA22-AB22 -> 185542.04 | AD22: =AD21*(1+ASSUMPTIONS!$D$59)+AB22+MAX(AC22,0)*0.2 -> 1492850 | AE22: =(E22+F22)-(N22+O22) -> -2081.6887 | AF22: =(E22+F22)-(W22+X22) -> -14278.292 | AG22: =L22-U22 -> 1729.8223 | AH22: =L22-AD22 -> 178252.03
A23: 18 | B23: 2044 | C23: 54 | D23: Research Scientist | E23: =ASSUMPTIONS!$B$21*(1+ASSUMPTIONS!$B$23)^10*12+ASSUMPTIONS!$B$48*(1+ASSUMPTIONS!$B$51)^4 -> 326529.08 | F23: =ASSUMPTIONS!$B$33*(1+ASSUMPTIONS!$B$34)^10*12 -> 8738.1821 | G23: =MAX((E23-F23)*(ASSUMPTIONS!$B$66+ASSUMPTIONS!$B$67),0) -> 98515.178 | H23: =ASSUMPTIONS!$B$26*(1+ASSUMPTIONS!$B$27)^10 -> 244.59278 | I23: =ASSUMPTIONS!$B$70*12*(1+ASSUMPTIONS!$B$71)^18 -> 48903.82 | J23: =ASSUMPTIONS!$B$61*12 -> 6000 | K23: =E23+F23-G23-H23-I23-J23 -> 181603.67 | L23: =L22*(1+ASSUMPTIONS!$B$59)+J23+MAX(K23,0)*0.2 -> 1830399.9 | M23: CS / Tech Job | N23: =ASSUMPTIONS!$C$47*(1+ASSUMPTIONS!$B$51)^16 -> 327771.72 | O23: =ASSUMPTIONS!$C$33*(1+ASSUMPTIONS!$C$34)^16*12 -> 10312.876 | P23: =MAX((N23-O23)*(ASSUMPTIONS!$C$65+ASSUMPTIONS!$C$67),0) -> 92063.064 | Q23: =ASSUMPTIONS!$C$28*(1+ASSUMPTIONS!$C$29)^16 -> 10277.828 | R23: =ASSUMPTIONS!$B$70*12*(1+ASSUMPTIONS!$B$71)^18 -> 48903.82 | S23: =ASSUMPTIONS!$C$61*12 -> 6000 | T23: =N23+O23-P23-Q23-R23-S23 -> 180839.88 | U23: =U22*(1+ASSUMPTIONS!$C$59)+S23+MAX(T23,0)*0.2 -> 1828396.3 | V23: Research Scientist | W23: =ASSUMPTIONS!$D$48*(1+ASSUMPTIONS!$B$51)^10 -> 340456.19 | X23: =ASSUMPTIONS!$D$33*(1+ASSUMPTIONS!$D$34)^16*12 -> 10312.876 | Y23: =MAX((W23-X23)*(ASSUMPTIONS!$D$66+ASSUMPTIONS!$D$67),0) -> 102344.43 | Z23: =ASSUMPTIONS!$D$28*(1+ASSUMPTIONS!$D$29)^16 -> 0 | AA23: =ASSUMPTIONS!$B$70*12*(1+ASSUMPTIONS!$B$71)^18 -> 48903.82 | AB23: =ASSUMPTIONS!$D$61*12 -> 6000 | AC23: =W23+X23-Y23-Z23-AA23-AB23 -> 193520.82 | AD23: =AD22*(1+ASSUMPTIONS!$D$59)+AB23+MAX(AC23,0)*0.2 -> 1642053.7 | AE23: =(E23+F23)-(N23+O23) -> -2817.3327 | AF23: =(E23+F23)-(W23+X23) -> -15501.8 | AG23: =L23-U23 -> 2003.6676 | AH23: =L23-AD23 -> 188346.24
A24: 19 | B24: 2045 | C24: 55 | D24: Research Scientist | E24: =ASSUMPTIONS!$B$21*(1+ASSUMPTIONS!$B$23)^11*12+ASSUMPTIONS!$B$48*(1+ASSUMPTIONS!$B$51)^5 -> 338900.7 | F24: =ASSUMPTIONS!$B$33*(1+ASSUMPTIONS!$B$34)^11*12 -> 8982.8512 | G24: =MAX((E24-F24)*(ASSUMPTIONS!$B$66+ASSUMPTIONS!$B$67),0) -> 102274.53 | H24: =ASSUMPTIONS!$B$26*(1+ASSUMPTIONS!$B$27)^11 -> 251.93056 | I24: =ASSUMPTIONS!$B$70*12*(1+ASSUMPTIONS!$B$71)^19 -> 50370.934 | J24: =ASSUMPTIONS!$B$61*12 -> 6000 | K24: =E24+F24-G24-H24-I24-J24 -> 188986.16 | L24: =L23*(1+ASSUMPTIONS!$B$59)+J24+MAX(K24,0)*0.2 -> 2002325.1 | M24: CS / Tech Job | N24: =ASSUMPTIONS!$C$47*(1+ASSUMPTIONS!$B$51)^17 -> 340882.59 | O24: =ASSUMPTIONS!$C$33*(1+ASSUMPTIONS!$C$34)^17*12 -> 10601.636 | P24: =MAX((N24-O24)*(ASSUMPTIONS!$C$65+ASSUMPTIONS!$C$67),0) -> 95781.476 | Q24: =ASSUMPTIONS!$C$28*(1+ASSUMPTIONS!$C$29)^17 -> 11100.054 | R24: =ASSUMPTIONS!$B$70*12*(1+ASSUMPTIONS!$B$71)^19 -> 50370.934 | S24: =ASSUMPTIONS!$C$61*12 -> 6000 | T24: =N24+O24-P24-Q24-R24-S24 -> 188231.76 | U24: =U23*(1+ASSUMPTIONS!$C$59)+S24+MAX(T24,0)*0.2 -> 2000030.3 | V24: Research Scientist | W24: =ASSUMPTIONS!$D$48*(1+ASSUMPTIONS!$B$51)^11 -> 354074.43 | X24: =ASSUMPTIONS!$D$33*(1+ASSUMPTIONS!$D$34)^17*12 -> 10601.636 | Y24: =MAX((W24-X24)*(ASSUMPTIONS!$D$66+ASSUMPTIONS!$D$67),0) -> 106476.57 | Z24: =ASSUMPTIONS!$D$28*(1+ASSUMPTIONS!$D$29)^17 -> 0 | AA24: =ASSUMPTIONS!$B$70*12*(1+ASSUMPTIONS!$B$71)^19 -> 50370.934 | AB24: =ASSUMPTIONS!$D$61*12 -> 6000 | AC24: =W24+X24-Y24-Z24-AA24-AB24 -> 201828.57 | AD24: =AD23*(1+ASSUMPTIONS!$D$59)+AB24+MAX(AC24,0)*0.2 -> 1803363.2 | AE24: =(E24+F24)-(N24+O24) -> -3600.669 | AF24: =(E24+F24)-(W24+X24) -> -16792.515 | AG24: =L24-U24 -> 2294.8036 | AH24: =L24-AD24 -> 198961.99
A25: 20 | B25: 2046 | C25: 56 | D25: Research Scientist | E25: =ASSUMPTIONS!$B$21*(1+ASSUMPTIONS!$B$23)^12*12+ASSUMPTIONS!$B$48*(1+ASSUMPTIONS!$B$51)^6 -> 351747.88 | F25: =ASSUMPTIONS!$B$33*(1+ASSUMPTIONS!$B$34)^12*12 -> 9234.3711 | G25: =MAX((E25-F25)*(ASSUMPTIONS!$B$66+ASSUMPTIONS!$B$67),0) -> 106179.19 | H25: =ASSUMPTIONS!$B$26*(1+ASSUMPTIONS!$B$27)^12 -> 259.48848 | I25: =ASSUMPTIONS!$B$70*12*(1+ASSUMPTIONS!$B$71)^20 -> 51882.062 | J25: =ASSUMPTIONS!$B$61*12 -> 6000 | K25: =E25+F25-G25-H25-I25-J25 -> 196661.52 | L25: =L24*(1+ASSUMPTIONS!$B$59)+J25+MAX(K25,0)*0.2 -> 2187820.2 | M25: CS / Tech Job | N25: =ASSUMPTIONS!$C$47*(1+ASSUMPTIONS!$B$51)^18 -> 354517.89 | O25: =ASSUMPTIONS!$C$33*(1+ASSUMPTIONS!$C$34)^18*12 -> 10898.482 | P25: =MAX((N25-O25)*(ASSUMPTIONS!$C$65+ASSUMPTIONS!$C$67),0) -> 99649.628 | Q25: =ASSUMPTIONS!$C$28*(1+ASSUMPTIONS!$C$29)^18 -> 11988.058 | R25: =ASSUMPTIONS!$B$70*12*(1+ASSUMPTIONS!$B$71)^20 -> 51882.062 | S25: =ASSUMPTIONS!$C$61*12 -> 6000 | T25: =N25+O25-P25-Q25-R25-S25 -> 195896.62 | U25: =U24*(1+ASSUMPTIONS!$C$59)+S25+MAX(T25,0)*0.2 -> 2185211.8 | V25: Research Scientist | W25: =ASSUMPTIONS!$D$48*(1+ASSUMPTIONS!$B$51)^12 -> 368237.41 | X25: =ASSUMPTIONS!$D$33*(1+ASSUMPTIONS!$D$34)^18*12 -> 10898.482 | Y25: =MAX((W25-X25)*(ASSUMPTIONS!$D$66+ASSUMPTIONS!$D$67),0) -> 110775.07 | Z25: =ASSUMPTIONS!$D$28*(1+ASSUMPTIONS!$D$29)^18 -> 0 | AA25: =ASSUMPTIONS!$B$70*12*(1+ASSUMPTIONS!$B$71)^20 -> 51882.062 | AB25: =ASSUMPTIONS!$D$61*12 -> 6000 | AC25: =W25+X25-Y25-Z25-AA25-AB25 -> 210478.76 | AD25: =AD24*(1+ASSUMPTIONS!$D$59)+AB25+MAX(AC25,0)*0.2 -> 1977694.3 | AE25: =(E25+F25)-(N25+O25) -> -4434.1167 | AF25: =(E25+F25)-(W25+X25) -> -18153.637 | AG25: =L25-U25 -> 2608.4183 | AH25: =L25-AD25 -> 210125.88
A26: 21 | B26: 2047 | C26: 57 | D26: Research Scientist | E26: =ASSUMPTIONS!$B$21*(1+ASSUMPTIONS!$B$23)^13*12+ASSUMPTIONS!$B$48*(1+ASSUMPTIONS!$B$51)^7 -> 365089.11 | F26: =ASSUMPTIONS!$B$33*(1+ASSUMPTIONS!$B$34)^13*12 -> 9492.9335 | G26: =MAX((E26-F26)*(ASSUMPTIONS!$B$66+ASSUMPTIONS!$B$67),0) -> 110234.81 | H26: =ASSUMPTIONS!$B$26*(1+ASSUMPTIONS!$B$27)^13 -> 267.27314 | I26: =ASSUMPTIONS!$B$70*12*(1+ASSUMPTIONS!$B$71)^21 -> 53438.524 | J26: =ASSUMPTIONS!$B$61*12 -> 6000 | K26: =E26+F26-G26-H26-I26-J26 -> 204641.43 | L26: =L25*(1+ASSUMPTIONS!$B$59)+J26+MAX(K26,0)*0.2 -> 2387895.9 | M26: CS / Tech Job | N26: =ASSUMPTIONS!$C$47*(1+ASSUMPTIONS!$B$51)^19 -> 368698.61 | O26: =ASSUMPTIONS!$C$33*(1+ASSUMPTIONS!$C$34)^19*12 -> 11203.639 | P26: =MAX((N26-O26)*(ASSUMPTIONS!$C$65+ASSUMPTIONS!$C$67),0) -> 103673.54 | Q26: =ASSUMPTIONS!$C$28*(1+ASSUMPTIONS!$C$29)^19 -> 12947.103 | R26: =ASSUMPTIONS!$B$70*12*(1+ASSUMPTIONS!$B$71)^21 -> 53438.524 | S26: =ASSUMPTIONS!$C$61*12 -> 6000 | T26: =N26+O26-P26-Q26-R26-S26 -> 203843.08 | U26: =U25*(1+ASSUMPTIONS!$C$59)+S26+MAX(T26,0)*0.2 -> 2384945.2 | V26: Research Scientist | W26: =ASSUMPTIONS!$D$48*(1+ASSUMPTIONS!$B$51)^13 -> 382966.91 | X26: =ASSUMPTIONS!$D$33*(1+ASSUMPTIONS!$D$34)^19*12 -> 11203.639 | Y26: =MAX((W26-X26)*(ASSUMPTIONS!$D$66+ASSUMPTIONS!$D$67),0) -> 115246.61 | Z26: =ASSUMPTIONS!$D$28*(1+ASSUMPTIONS!$D$29)^19 -> 0 | AA26: =ASSUMPTIONS!$B$70*12*(1+ASSUMPTIONS!$B$71)^21 -> 53438.524 | AB26: =ASSUMPTIONS!$D$61*12 -> 6000 | AC26: =W26+X26-Y26-Z26-AA26-AB26 -> 219485.41 | AD26: =AD25*(1+ASSUMPTIONS!$D$59)+AB26+MAX(AC26,0)*0.2 -> 2166030 | AE26: =(E26+F26)-(N26+O26) -> -5320.2062 | AF26: =(E26+F26)-(W26+X26) -> -19588.507 | AG26: =L26-U26 -> 2950.6778 | AH26: =L26-AD26 -> 221865.9
A27: 22 | B27: 2048 | C27: 58 | D27: Research Scientist | E27: =ASSUMPTIONS!$B$21*(1+ASSUMPTIONS!$B$23)^14*12+ASSUMPTIONS!$B$48*(1+ASSUMPTIONS!$B$51)^8 -> 378943.57 | F27: =ASSUMPTIONS!$B$33*(1+ASSUMPTIONS!$B$34)^14*12 -> 9758.7356 | G27: =MAX((E27-F27)*(ASSUMPTIONS!$B$66+ASSUMPTIONS!$B$67),0) -> 114447.3 | H27: =ASSUMPTIONS!$B$26*(1+ASSUMPTIONS!$B$27)^14 -> 275.29133 | I27: =ASSUMPTIONS!$B$70*12*(1+ASSUMPTIONS!$B$71)^22 -> 55041.68 | J27: =ASSUMPTIONS!$B$61*12 -> 6000 | K27: =E27+F27-G27-H27-I27-J27 -> 212938.04 | L27: =L26*(1+ASSUMPTIONS!$B$59)+J27+MAX(K27,0)*0.2 -> 2603636.2 | M27: CS / Tech Job | N27: =ASSUMPTIONS!$C$47*(1+ASSUMPTIONS!$B$51)^20 -> 383446.55 | O27: =ASSUMPTIONS!$C$33*(1+ASSUMPTIONS!$C$34)^20*12 -> 11517.341 | P27: =MAX((N27-O27)*(ASSUMPTIONS!$C$65+ASSUMPTIONS!$C$67),0) -> 107859.47 | Q27: =ASSUMPTIONS!$C$28*(1+ASSUMPTIONS!$C$29)^20 -> 13982.871 | R27: =ASSUMPTIONS!$B$70*12*(1+ASSUMPTIONS!$B$71)^22 -> 55041.68 | S27: =ASSUMPTIONS!$C$61*12 -> 6000 | T27: =N27+O27-P27-Q27-R27-S27 -> 212079.87 | U27: =U26*(1+ASSUMPTIONS!$C$59)+S27+MAX(T27,0)*0.2 -> 2600307.4 | V27: Research Scientist | W27: =ASSUMPTIONS!$D$48*(1+ASSUMPTIONS!$B$51)^14 -> 398285.58 | X27: =ASSUMPTIONS!$D$33*(1+ASSUMPTIONS!$D$34)^20*12 -> 11517.341 | Y27: =MAX((W27-X27)*(ASSUMPTIONS!$D$66+ASSUMPTIONS!$D$67),0) -> 119898.15 | Z27: =ASSUMPTIONS!$D$28*(1+ASSUMPTIONS!$D$29)^20 -> 0 | AA27: =ASSUMPTIONS!$B$70*12*(1+ASSUMPTIONS!$B$71)^22 -> 55041.68 | AB27: =ASSUMPTIONS!$D$61*12 -> 6000 | AC27: =W27+X27-Y27-Z27-AA27-AB27 -> 228863.09 | AD27: =AD26*(1+ASSUMPTIONS!$D$59)+AB27+MAX(AC27,0)*0.2 -> 2369424.7 | AE27: =(E27+F27)-(N27+O27) -> -6261.5835 | AF27: =(E27+F27)-(W27+X27) -> -21100.616 | AG27: =L27-U27 -> 3328.8588 | AH27: =L27-AD27 -> 234211.5
A28: 23 | B28: 2049 | C28: 59 | D28: Research Scientist | E28: =ASSUMPTIONS!$B$21*(1+ASSUMPTIONS!$B$23)^15*12+ASSUMPTIONS!$B$48*(1+ASSUMPTIONS!$B$51)^9 -> 393331.24 | F28: =ASSUMPTIONS!$B$33*(1+ASSUMPTIONS!$B$34)^15*12 -> 10031.98 | G28: =MAX((E28-F28)*(ASSUMPTIONS!$B$66+ASSUMPTIONS!$B$67),0) -> 118822.77 | H28: =ASSUMPTIONS!$B$26*(1+ASSUMPTIONS!$B$27)^15 -> 283.55007 | I28: =ASSUMPTIONS!$B$70*12*(1+ASSUMPTIONS!$B$71)^23 -> 56692.93 | J28: =ASSUMPTIONS!$B$61*12 -> 6000 | K28: =E28+F28-G28-H28-I28-J28 -> 221563.97 | L28: =L27*(1+ASSUMPTIONS!$B$59)+J28+MAX(K28,0)*0.2 -> 2836203.6 | M28: CS / Tech Job | N28: =ASSUMPTIONS!$C$47*(1+ASSUMPTIONS!$B$51)^21 -> 398784.41 | O28: =ASSUMPTIONS!$C$33*(1+ASSUMPTIONS!$C$34)^21*12 -> 11839.827 | P28: =MAX((N28-O28)*(ASSUMPTIONS!$C$65+ASSUMPTIONS!$C$67),0) -> 112213.93 | Q28: =ASSUMPTIONS!$C$28*(1+ASSUMPTIONS!$C$29)^21 -> 15101.501 | R28: =ASSUMPTIONS!$B$70*12*(1+ASSUMPTIONS!$B$71)^23 -> 56692.93 | S28: =ASSUMPTIONS!$C$61*12 -> 6000 | T28: =N28+O28-P28-Q28-R28-S28 -> 220615.88 | U28: =U27*(1+ASSUMPTIONS!$C$59)+S28+MAX(T28,0)*0.2 -> 2832452.1 | V28: Research Scientist | W28: =ASSUMPTIONS!$D$48*(1+ASSUMPTIONS!$B$51)^15 -> 414217.01 | X28: =ASSUMPTIONS!$D$33*(1+ASSUMPTIONS!$D$34)^21*12 -> 11839.827 | Y28: =MAX((W28-X28)*(ASSUMPTIONS!$D$66+ASSUMPTIONS!$D$67),0) -> 124736.93 | Z28: =ASSUMPTIONS!$D$28*(1+ASSUMPTIONS!$D$29)^21 -> 0 | AA28: =ASSUMPTIONS!$B$70*12*(1+ASSUMPTIONS!$B$71)^23 -> 56692.93 | AB28: =ASSUMPTIONS!$D$61*12 -> 6000 | AC28: =W28+X28-Y28-Z28-AA28-AB28 -> 238626.98 | AD28: =AD27*(1+ASSUMPTIONS!$D$59)+AB28+MAX(AC28,0)*0.2 -> 2589009.9 | AE28: =(E28+F28)-(N28+O28) -> -7261.0159 | AF28: =(E28+F28)-(W28+X28) -> -22693.61 | AG28: =L28-U28 -> 3751.4976 | AH28: =L28-AD28 -> 247193.71
A29: 24 | B29: 2050 | C29: 60 | D29: Research Scientist | E29: =ASSUMPTIONS!$B$21*(1+ASSUMPTIONS!$B$23)^16*12+ASSUMPTIONS!$B$48*(1+ASSUMPTIONS!$B$51)^10 -> 408272.86 | F29: =ASSUMPTIONS!$B$33*(1+ASSUMPTIONS!$B$34)^16*12 -> 10312.876 | G29: =MAX((E29-F29)*(ASSUMPTIONS!$B$66+ASSUMPTIONS!$B$67),0) -> 123367.59 | H29: =ASSUMPTIONS!$B$26*(1+ASSUMPTIONS!$B$27)^16 -> 292.05657 | I29: =ASSUMPTIONS!$B$70*12*(1+ASSUMPTIONS!$B$71)^24 -> 58393.718 | J29: =ASSUMPTIONS!$B$61*12 -> 6000 | K29: =E29+F29-G29-H29-I29-J29 -> 230532.36 | L29: =L28*(1+ASSUMPTIONS!$B$59)+J29+MAX(K29,0)*0.2 -> 3086844.3 | M29: CS / Tech Job | N29: =ASSUMPTIONS!$C$47*(1+ASSUMPTIONS!$B$51)^22 -> 414735.79 | O29: =ASSUMPTIONS!$C$33*(1+ASSUMPTIONS!$C$34)^22*12 -> 12171.342 | P29: =MAX((N29-O29)*(ASSUMPTIONS!$C$65+ASSUMPTIONS!$C$67),0) -> 116743.69 | Q29: =ASSUMPTIONS!$C$28*(1+ASSUMPTIONS!$C$29)^22 -> 16309.621 | R29: =ASSUMPTIONS!$B$70*12*(1+ASSUMPTIONS!$B$71)^24 -> 58393.718 | S29: =ASSUMPTIONS!$C$61*12 -> 6000 | T29: =N29+O29-P29-Q29-R29-S29 -> 229460.1 | U29: =U28*(1+ASSUMPTIONS!$C$59)+S29+MAX(T29,0)*0.2 -> 3082615.7 | V29: Research Scientist | W29: =ASSUMPTIONS!$D$48*(1+ASSUMPTIONS!$B$51)^16 -> 430785.69 | X29: =ASSUMPTIONS!$D$33*(1+ASSUMPTIONS!$D$34)^22*12 -> 12171.342 | Y29: =MAX((W29-X29)*(ASSUMPTIONS!$D$66+ASSUMPTIONS!$D$67),0) -> 129770.45 | Z29: =ASSUMPTIONS!$D$28*(1+ASSUMPTIONS!$D$29)^22 -> 0 | AA29: =ASSUMPTIONS!$B$70*12*(1+ASSUMPTIONS!$B$71)^24 -> 58393.718 | AB29: =ASSUMPTIONS!$D$61*12 -> 6000 | AC29: =W29+X29-Y29-Z29-AA29-AB29 -> 248792.86 | AD29: =AD28*(1+ASSUMPTIONS!$D$59)+AB29+MAX(AC29,0)*0.2 -> 2825999.1 | AE29: =(E29+F29)-(N29+O29) -> -8321.3967 | AF29: =(E29+F29)-(W29+X29) -> -24371.295 | AG29: =L29-U29 -> 4228.555 | AH29: =L29-AD29 -> 260845.17
