Workbook

Sheet ASSUMPTIONS
A1: LONG-TERM FINANCIAL PROJECTION ASSUMPTIONS
A2: All values below drive the PROJECTIONS sheet. Blue cells with yellow background are editable inputs.
A4: Assumption | B4: Path A (Stay) | C4: Path B (Separate) | D4: Source / Notes
A6: SERVICE & TIMELINE
A7: TAFMS Date (entered service) | B7: Feb 2014 | C7: Feb 2014 | D7: Resume / service records
A8: Current Date (base year) | B8: 2026 | C8: 2026 | D8: Projection start year
A9: Years of Service at Projection Start | B9: 12.1 | C9: 12.1 | D9: 2026 minus 2014
A10: Separation Date | B10: N/A (stays in) | C10: Nov 2027 | D10: Roadmap: Nov 2027 if CNODP rejected
A11: Years Until Separation | B11: N/A | C11: 1.67 | D11: From Mar 2026 to Nov 2027
A12: Military Retirement Year (20 yrs) | B12: 2034 | C12: N/A | D12: Feb 2014 + 20 yrs = Feb 2034. Projection year 2034 unchanged — no formula impact.
A13: Years Until Retirement | B13: 7.9 | C13: N/A | D13: Mar 2026 to Feb 2034 = 7 yr 11 mo ≈ 8 yrs. Year-based projection logic unaffected.
A15: CURRENT MILITARY COMPENSATION (MONTHLY)
A16: Base Pay (Monthly) | B16: =INCOME!B6 -> 5591.66 | C16: =INCOME!B6 -> 5591.66 | D16: From INCOME sheet
A17: BAH (Housing Allowance) | B17: =INCOME!B7 -> 2741.66 | C17: =INCOME!B7 -> 2741.66 | D17: From INCOME sheet — tax-free
A18: BAS (Food Allowance) | B18: =INCOME!B8 -> 477 | C18: =INCOME!B8 -> 477 | D18: 2025 BAS: $465.77/mo (From INCOME sheet, user has $477)
A19: Current Monthly TSP Contribution | B19: 700 | C19: 700 | D19: 2025 limit: $23,500/yr ($1,958/mo). Catch-up 50+: add $7,500. Source: tsp.gov
A20: Gross Monthly Income (Current) | B20: =INCOME!B97 -> 8810.32 | C20: =INCOME!B97 -> 8810.32 | D20: From INCOME sheet
A21: Net Monthly Income (Current) | B21: =INCOME!B99 -> 7720.37 | C21: =INCOME!B99 -> 7720.37 | D21: From INCOME sheet
A23: MILITARY RETIREMENT & PENSION
A24: Retirement System | B24: High-3 | C24: N/A | D24: Pre-2018 entry → High-3 (not BRS)
A25: High-3 Average Base Pay (est. at retirement) | B25: 7266 | C25: 0 | D25: Est. E-8 avg of highest 36 mo base pay at 20 yrs (2024 tables + ~2.5%/yr raises)
A26: Pension Multiplier (2.5% × years) | B26: 0.5 | C26: 0 | D26: 2.5% × 20 years = 50%
A27: Monthly Pension (before tax) | B27: 3633 | C27: 0 | D27: High3 x multiplier. $7,266 x 50%
A28: Annual Pension (before tax) | B28: 43596 | C28: 0 | D28: Monthly × 12
A29: Pension COLA (annual increase) | B29: 0.028 | C29: 0 | D29: 2026 COLA: 2.8% (CPI-W based). Long-term avg ~2.5%. Source: militarypay.defense.gov
A30: Pension Start Age | B30: 40 | C30: N/A | D30: Retire at ~40 (entered at ~20, retire at 20 yrs)
A31: Life Expectancy (for pension valuation) | B31: 82 | C31: 82 | D31: US male average ~76, military retirees tend higher | E31: [QUESTION] Life expectancy 82 used for pension valuation. Extend to 40 years for more conservative military retiree estimate.
A33: HEALTHCARE COSTS (ANNUAL)
A34: Active Duty Healthcare Cost | B34: 0 | C34: 0 | D34: TRICARE Active Duty: $0 premiums
A35: TRICARE Retiree Annual Cost | B35: 182 | C35: N/A | D35: TRICARE Select Group A retiree: $181.92/yr individual (2025). Source: tricare.mil | E35: [QUESTION] TRICARE rate uses 3%/yr inflation. Verify current TRICARE retiree premium — may be adjusted by Congress differently than CPI.
A36: Civilian Health Insurance (annual) | B36: N/A | C36: 3000 | D36: Employer-sponsored employee share: ~$1,303/yr (2025 KFF). +copays/deductibles ~$3,000 total OOP. Source: KFF | E36: [CONCERN] Model gap: healthcare costs for Path A PhD phase (2035-2039) and gap year not separately itemized — review actual school-location costs
A37: Civilian Healthcare Inflation | B37: N/A | C37: 0.08 | D37: 2026 Covered CA: 10.3% increase. Historical ~8%/yr. Source: CHCF/Covered California
A38: TRICARE Retiree Annual Increase | B38: 0.03 | C38: N/A | D38: TRICARE adjustments ~3%/yr
A39: Lifetime Healthcare Savings (Path A vs B) | B39: See PROJECTIONS | C39: See PROJECTIONS | D39: Major advantage of military retirement
A41: VA DISABILITY & BENEFITS
A42: Assumed VA Disability Rating | B42: 0.3 | C42: 0.3 | D42: 30% — conservative estimate, common for 12+ yr service | E42: [GAP] VA disability rating assumed at 30%. Actual rating unknown until filed. 10% = $171/mo, 50% = $1,075/mo — significant range.
A43: VA Disability Monthly Payment | B43: 552.47 | C43: 552.47 | D43: 30% single no dep: $537.42 (2025) + 2.8% COLA = $552.47 (2026). Source: va.gov
A44: VA Disability COLA (annual) | B44: 0.028 | C44: 0.028 | D44: 2026 COLA: 2.8%. 5yr avg ~3.4% (includes 8.7% spike). Long-term avg ~2.5%. Source: va.gov
A45: VA Disability Tax Status | B45: Tax-free | C45: Tax-free | D45: 100% tax-exempt at all disability ratings
A46: VA Disability Start (Path A) | B46: At retirement (2034) | C46: At separation (2027) | D46: Claims typically filed at transition
...

Sheet PROJECTIONS
A1: 30-YEAR FINANCIAL PROJECTION: PATH A (STAY & RETIRE) vs PATH B (SEPARATE & PHD)
A2: All projections driven by ASSUMPTIONS sheet. Pension, VA disability, and GI Bill values are tax-free income.
C3: PATH A: Stay → Retire 2034 → PhD → Research Scientist | L3: PATH B: Separate Nov 2027 → PhD 2028 → Research Scientist | U3: COMPARISON (Path A Advantage)
A4: Yr # | B4: Year | C4: Status | D4: Gross Income | E4: Tax-Free Income | F4: Taxes | G4: Healthcare | H4: Living Expenses | I4: Ret. Savings | J4: Net Cash Flow | K4: Portfolio | L4: Status | M4: Gross Income | N4: Tax-Free Income | O4: Taxes | P4: Healthcare | Q4: Living Expenses | R4: Ret. Savings | S4: Net Cash Flow | T4: Portfolio | U4: Income Diff | V4: HC Savings | W4: CF Diff | X4: Portfolio Diff | Y4: Cumul. Adv.
A5: 0 | B5: 2026 | C5: Active Duty | D5: =ASSUMPTIONS!B20*12*(1+ASSUMPTIONS!B67)^0 -> 105723.84 | E5: =(INCOME!B7+INCOME!B8)*12*(1+ASSUMPTIONS!B67)^0 -> 38623.92 | F5: =MAX((D5-E5)*(ASSUMPTIONS!B81+ASSUMPTIONS!B84),0) -> 12748.985 | G5: 0 | H5: =ASSUMPTIONS!B85*12*(1+ASSUMPTIONS!B86)^0 -> 28725.84 | I5: =ASSUMPTIONS!B75*12 -> 22800 | J5: =D5+E5-F5-G5-H5-I5 -> 80072.935 | K5: =ASSUMPTIONS!B70+ASSUMPTIONS!B71+ASSUMPTIONS!B72+ASSUMPTIONS!B73+I5+MAX(J5,0)*0.2 -> 188814.59 | L5: Active Duty | M5: =ASSUMPTIONS!B20*12*(1+ASSUMPTIONS!B67)^0 -> 105723.84 | N5: =(INCOME!B7+INCOME!B8)*12*(1+ASSUMPTIONS!B67)^0 -> 38623.92 | O5: =MAX((M5-N5)*(ASSUMPTIONS!B81+ASSUMPTIONS!B84),0) -> 12748.985 | P5: 0 | Q5: =ASSUMPTIONS!B85*12*(1+ASSUMPTIONS!B86)^0 -> 28725.84 | R5: =ASSUMPTIONS!B75*12 -> 22800 | S5: =M5+N5-O5-P5-Q5-R5 -> 80072.935 | T5: =ASSUMPTIONS!B70+ASSUMPTIONS!B71+ASSUMPTIONS!B72+ASSUMPTIONS!B73+R5+MAX(S5,0)*0.2 -> 188814.59 | U5: =(D5+E5)-(M5+N5) -> 0 | V5: =P5-G5 -> 0 | W5: =J5-S5 -> 0 | X5: =K5-T5 -> 0 | Y5: =W5 -> 0
A6: 1 | B6: 2027 | C6: Active Duty | D6: =ASSUMPTIONS!B20*12*(1+ASSUMPTIONS!B67)^1 -> 108366.94 | E6: =(INCOME!B7+INCOME!B8)*12*(1+ASSUMPTIONS!B67)^1 -> 39589.518 | F6: =MAX((D6-E6)*(ASSUMPTIONS!B81+ASSUMPTIONS!B84),0) -> 13067.709 | G6: 0 | H6: =ASSUMPTIONS!B85*12*(1+ASSUMPTIONS!B86)^1 -> 29587.615 | I6: =ASSUMPTIONS!B75*12 -> 22800 | J6: =D6+E6-F6-G6-H6-I6 -> 82501.129 | K6: =K5*(1+ASSUMPTIONS!B74)+I6+MAX(J6,0)*0.2 -> 241331.83 | L6: Active Duty | M6: =ASSUMPTIONS!B20*12*(1+ASSUMPTIONS!B67)^1 -> 108366.94 | N6: =(INCOME!B7+INCOME!B8)*12*(1+ASSUMPTIONS!B67)^1 -> 39589.518 | O6: =MAX((M6-N6)*(ASSUMPTIONS!B81+ASSUMPTIONS!B84),0) -> 13067.709 | P6: 0 | Q6: =ASSUMPTIONS!B85*12*(1+ASSUMPTIONS!B86)^1 -> 29587.615 | R6: =ASSUMPTIONS!B75*12 -> 22800 | S6: =M6+N6-O6-P6-Q6-R6 -> 82501.129 | T6: =T5*(1+ASSUMPTIONS!B74)+R6+MAX(S6,0)*0.2 -> 241331.83 | U6: =(D6+E6)-(M6+N6) -> 0 | V6: =P6-G6 -> 0 | W6: =J6-S6 -> 0 | X6: =K6-T6 -> 0 | Y6: =Y5+W6 -> 0
A7: 2 | B7: 2028 | C7: Active Duty | D7: =ASSUMPTIONS!B20*12*(1+ASSUMPTIONS!B67)^2 -> 111076.11 | E7: =(INCOME!B7+INCOME!B8)*12*(1+ASSUMPTIONS!B67)^2 -> 40579.256 | F7: =MAX((D7-E7)*(ASSUMPTIONS!B81+ASSUMPTIONS!B84),0) -> 13394.402 | G7: 0 | H7: =ASSUMPTIONS!B85*12*(1+ASSUMPTIONS!B86)^2 -> 30475.244 | I7: =ASSUMPTIONS!B75*12 -> 22800 | J7: =D7+E7-F7-G7-H7-I7 -> 84985.72 | K7: =K6*(1+ASSUMPTIONS!B74)+I7+MAX(J7,0)*0.2 -> 298022.21 | L7: Gap Year | M7: =ASSUMPTIONS!C43*12 -> 6629.64 | N7: =ASSUMPTIONS!C43*12 -> 6629.64 | O7: 0 | P7: 2000 | Q7: =ASSUMPTIONS!B85*12*(1+ASSUMPTIONS!B86)^2 -> 30475.244 | R7: =ASSUMPTIONS!B77*12 -> 0 | S7: =M7+N7-O7-P7-Q7-R7 -> -19215.964 | T7: =T6*(1+ASSUMPTIONS!B74)+R7+MAX(S7,0)*0.2 -> 258225.06 | U7: =(D7+E7)-(M7+N7) -> 138396.09 | V7: =P7-G7 -> 2000 | W7: =J7-S7 -> 104201.68 | X7: =K7-T7 -> 39797.144 | Y7: =Y6+W7 -> 104201.68
A8: 3 | B8: 2029 | C8: Active Duty | D8: =ASSUMPTIONS!B20*12*(1+ASSUMPTIONS!B67)^3 -> 113853.01 | E8: =(INCOME!B7+INCOME!B8)*12*(1+ASSUMPTIONS!B67)^3 -> 41593.737 | F8: =MAX((D8-E8)*(ASSUMPTIONS!B81+ASSUMPTIONS!B84),0) -> 13729.262 | G8: 0 | H8: =ASSUMPTIONS!B85*12*(1+ASSUMPTIONS!B86)^3 -> 31389.501 | I8: =ASSUMPTIONS!B75*12 -> 22800 | J8: =D8+E8-F8-G8-H8-I8 -> 87527.986 | K8: =K7*(1+ASSUMPTIONS!B74)+I8+MAX(J8,0)*0.2 -> 359189.36 | L8: PhD Student | M8: =ASSUMPTIONS!B62 -> 47000 | N8: =ASSUMPTIONS!B43*12*(1+ASSUMPTIONS!B44)^1+ASSUMPTIONS!B52*12+ASSUMPTIONS!B53 -> 67719.27 | O8: =MAX((M8-N8)*0.1,0) -> 0 | P8: 2000 | Q8: =ASSUMPTIONS!B85*12*(1+ASSUMPTIONS!B86)^3 -> 31389.501 | R8: =ASSUMPTIONS!B77*12 -> 0 | S8: =M8+N8-O8-P8-Q8-R8 -> 81329.769 | T8: =T7*(1+ASSUMPTIONS!B74)+R8+MAX(S8,0)*0.2 -> 292566.77 | U8: =(D8+E8)-(M8+N8) -> 40727.48 | V8: =P8-G8 -> 2000 | W8: =J8-S8 -> 6198.2174 | X8: =K8-T8 -> 66622.587 | Y8: =Y7+W8 -> 110399.9
A9: 4 | B9: 2030 | C9: Active Duty | D9: =ASSUMPTIONS!B20*12*(1+ASSUMPTIONS!B67)^4 -> 116699.34 | E9: =(INCOME!B7+INCOME!B8)*12*(1+ASSUMPTIONS!B67)^4 -> 42633.581 | F9: =MAX((D9-E9)*(ASSUMPTIONS!B81+ASSUMPTIONS!B84),0) -> 14072.494 | G9: 0 | H9: =ASSUMPTIONS!B85*12*(1+ASSUMPTIONS!B86)^4 -> 32331.186 | I9: =ASSUMPTIONS!B75*12 -> 22800 | J9: =D9+E9-F9-G9-H9-I9 -> 90129.238 | K9: =K8*(1+ASSUMPTIONS!B74)+I9+MAX(J9,0)*0.2 -> 425158.46 | L9: PhD Student | M9: =ASSUMPTIONS!B62 -> 47000 | N9: =ASSUMPTIONS!B43*12*(1+ASSUMPTIONS!B44)^2+ASSUMPTIONS!B52*12+ASSUMPTIONS!B53 -> 67910.097 | O9: =MAX((M9-N9)*0.1,0) -> 0 | P9: 2000 | Q9: =ASSUMPTIONS!B85*12*(1+ASSUMPTIONS!B86)^4 -> 32331.186 | R9: =ASSUMPTIONS!B77*12 -> 0 | S9: =M9+N9-O9-P9-Q9-R9 -> 80578.911 | T9: =T8*(1+ASSUMPTIONS!B74)+R9+MAX(S9,0)*0.2 -> 329162.23 | U9: =(D9+E9)-(M9+N9) -> 44422.821 | V9: =P9-G9 -> 2000 | W9: =J9-S9 -> 9550.327 | X9: =K9-T9 -> 95996.234 | Y9: =Y8+W9 -> 119950.23
A10: 5 | B10: 2031 | C10: Active Duty | D10: =ASSUMPTIONS!B20*12*(1+ASSUMPTIONS!B67)^5 -> 119616.82 | E10: =(INCOME!B7+INCOME!B8)*12*(1+ASSUMPTIONS!B67)^5 -> 43699.42 | F10: =MAX((D10-E10)*(ASSUMPTIONS!B81+ASSUMPTIONS!B84),0) -> 14424.306 | G10: 0 | H10: =ASSUMPTIONS!B85*12*(1+ASSUMPTIONS!B86)^5 -> 33301.122 | I10: =ASSUMPTIONS!B75*12 -> 22800 | J10: =D10+E10-F10-G10-H10-I10 -> 92790.813 | K10: =K9*(1+ASSUMPTIONS!B74)+I10+MAX(J10,0)*0.2 -> 496277.72 | L10: PhD Student | M10: =ASSUMPTIONS!B62 -> 47000 | N10: =ASSUMPTIONS!B43*12*(1+ASSUMPTIONS!B44)^3 -> 7202.2682 | O10: =MAX((M10-N10)*0.1,0) -> 3979.7732 | P10: 2000 | Q10: =ASSUMPTIONS!B85*12*(1+ASSUMPTIONS!B86)^5 -> 33301.122 | R10: =ASSUMPTIONS!B77*12 -> 0 | S10: =M10+N10-O10-P10-Q10-R10 -> 14921.373 | T10: =T9*(1+ASSUMPTIONS!B74)+R10+MAX(S10,0)*0.2 -> 355187.86 | U10: =(D10+E10)-(M10+N10) -> 109113.97 | V10: =P10-G10 -> 2000 | W10: =J10-S10 -> 77869.44 | X10: =K10-T10 -> 141089.86 | Y10: =Y9+W10 -> 197819.67
A11: 6 | B11: 2032 | C11: Active Duty | D11: =ASSUMPTIONS!B20*12*(1+ASSUMPTIONS!B67)^6 -> 122607.24 | E11: =(INCOME!B7+INCOME!B8)*12*(1+ASSUMPTIONS!B67)^6 -> 44791.906 | F11: =MAX((D11-E11)*(ASSUMPTIONS!B81+ASSUMPTIONS!B84),0) -> 14784.914 | G11: 0 | H11: =ASSUMPTIONS!B85*12*(1+ASSUMPTIONS!B86)^6 -> 34300.155 | I11: =ASSUMPTIONS!B75*12 -> 22800 | J11: =D11+E11-F11-G11-H11-I11 -> 95514.078 | K11: =K10*(1+ASSUMPTIONS!B74)+I11+MAX(J11,0)*0.2 -> 572919.97 | L11: PhD Student | M11: =ASSUMPTIONS!B62 -> 47000 | N11: =ASSUMPTIONS!B43*12*(1+ASSUMPTIONS!B44)^4 -> 7403.9317 | O11: =MAX((M11-N11)*0.1,0) -> 3959.6068 | P11: 2000 | Q11: =ASSUMPTIONS!B85*12*(1+ASSUMPTIONS!B86)^6 -> 34300.155 | R11: =ASSUMPTIONS!B77*12 -> 0 | S11: =M11+N11-O11-P11-Q11-R11 -> 14144.17 | T11: =T10*(1+ASSUMPTIONS!B74)+R11+MAX(S11,0)*0.2 -> 382879.84 | U11: =(D11+E11)-(M11+N11) -> 112995.22 | V11: =P11-G11 -> 2000 | W11: =J11-S11 -> 81369.909 | X11: =K11-T11 -> 190040.13 | Y11: =Y10+W11 -> 279189.58
A12: 7 | B12: 2033 | C12: Active Duty | D12: =ASSUMPTIONS!B20*12*(1+ASSUMPTIONS!B67)^7 -> 125672.42 | E12: =(INCOME!B7+INCOME!B8)*12*(1+ASSUMPTIONS!B67)^7 -> 45911.703 | F12: =MAX((D12-E12)*(ASSUMPTIONS!B81+ASSUMPTIONS!B84),0) -> 15154.537 | G12: 0 | H12: =ASSUMPTIONS!B85*12*(1+ASSUMPTIONS!B86)^7 -> 35329.16 | I12: =ASSUMPTIONS!B75*12 -> 22800 | J12: =D12+E12-F12-G12-H12-I12 -> 98300.429 | K12: =K11*(1+ASSUMPTIONS!B74)+I12+MAX(J12,0)*0.2 -> 655484.46 | L12: Research Scientist | M12: =ASSUMPTIONS!B64*(1+ASSUMPTIONS!B66)^0 -> 220000 | N12: =ASSUMPTIONS!B43*12*(1+ASSUMPTIONS!B44)^5 -> 7611.2418 | O12: =MAX((M12-N12)*(ASSUMPTIONS!B83+ASSUMPTIONS!B84),0) -> 65840.515 | P12: =ASSUMPTIONS!C36*(1+ASSUMPTIONS!C37)^0 -> 3000 | Q12: =ASSUMPTIONS!B85*12*(1+ASSUMPTIONS!B86)^7 -> 35329.16 | R12: =ASSUMPTIONS!B76*12 -> 6000 | S12: =M12+N12-O12-P12-Q12-R12 -> 117441.57 | T12: =T11*(1+ASSUMPTIONS!B74)+R12+MAX(S12,0)*0.2 -> 439169.74 | U12: =(D12+E12)-(M12+N12) -> -56027.116 | V12: =P12-G12 -> 3000 | W12: =J12-S12 -> -19141.137 | X12: =K12-T12 -> 216314.71 | Y12: =Y11+W12 -> 260048.44
A13: 8 | B13: 2034 | C13: Retirement Year | D13: =ASSUMPTIONS!B20*12*(1+ASSUMPTIONS!B67)^8*0.75+ASSUMPTIONS!B28*0.25 -> 107509.67 | E13: =(INCOME!B7+INCOME!B8)*12*(1+ASSUMPTIONS!B67)^8*0.75+ASSUMPTIONS!B43*12*0.25 -> 36952.032 | F13: =MAX((D13-E13)*(ASSUMPTIONS!B81+ASSUMPTIONS!B84),0) -> 13405.952 | G13: =ASSUMPTIONS!B35*0.25 -> 45.5 | H13: =ASSUMPTIONS!B85*12*(1+ASSUMPTIONS!B86)^8 -> 36389.035 | I13: =ASSUMPTIONS!B77*12 -> 0 | J13: =D13+E13-F13-G13-H13-I13 -> 94621.22 | K13: =K12*(1+ASSUMPTIONS!B74)+I13+MAX(J13,0)*0.2 -> 720292.61 | L13: Research Scientist | M13: =ASSUMPTIONS!B64*(1+ASSUMPTIONS!B66)^1 -> 228800 | N13: =ASSUMPTIONS!B43*12*(1+ASSUMPTIONS!B44)^6 -> 7824.3566 | O13: =MAX((M13-N13)*(ASSUMPTIONS!B83+ASSUMPTIONS!B84),0) -> 68502.449 | P13: =ASSUMPTIONS!C36*(1+ASSUMPTIONS!C37)^1 -> 3240 | Q13: =ASSUMPTIONS!B85*12*(1+ASSUMPTIONS!B86)^8 -> 36389.035 | R13: =ASSUMPTIONS!B76*12 -> 6000 | S13: =M13+N13-O13-P13-Q13-R13 -> 122492.87 | T13: =T12*(1+ASSUMPTIONS!B74)+R13+MAX(S13,0)*0.2 -> 500410.2 | U13: =(D13+E13)-(M13+N13) -> -92162.65 | V13: =P13-G13 -> 3194.5 | W13: =J13-S13 -> -27871.652 | X13: =K13-T13 -> 219882.41 | Y13: =Y12+W13 -> 232176.79
A14: 9 | B14: 2035 | C14: Retired + PhD | D14: =ASSUMPTIONS!B28*(1+ASSUMPTIONS!B29)^1+ASSUMPTIONS!B62 -> 91816.688 | E14: =ASSUMPTIONS!B43*12*(1+ASSUMPTIONS!B44)^1+ASSUMPTIONS!B52*12+ASSUMPTIONS!B53 -> 67719.27 | F14: =MAX((D14-E14)*(ASSUMPTIONS!B81+ASSUMPTIONS!B84),0) -> 4578.5094 | G14: =ASSUMPTIONS!B35*(1+ASSUMPTIONS!B38)^1 -> 187.46 | H14: =ASSUMPTIONS!B85*12*(1+ASSUMPTIONS!B86)^9 -> 37480.706 | I14: =ASSUMPTIONS!B77*12 -> 0 | J14: =D14+E14-F14-G14-H14-I14 -> 117289.28 | K14: =K13*(1+ASSUMPTIONS!B74)+I14+MAX(J14,0)*0.2 -> 794170.95 | L14: Research Scientist | M14: =ASSUMPTIONS!B64*(1+ASSUMPTIONS!B66)^2 -> 237952 | N14: =ASSUMPTIONS!B43*12*(1+ASSUMPTIONS!B44)^7 -> 8043.4386 | O14: =MAX((M14-N14)*(ASSUMPTIONS!B83+ASSUMPTIONS!B84),0) -> 71271.654 | P14: =ASSUMPTIONS!C36*(1+ASSUMPTIONS!C37)^2 -> 3499.2 | Q14: =ASSUMPTIONS!B85*12*(1+ASSUMPTIONS!B86)^9 -> 37480.706 | R14: =ASSUMPTIONS!B76*12 -> 6000 | S14: =M14+N14-O14-P14-Q14-R14 -> 127743.88 | T14: =T13*(1+ASSUMPTIONS!B74)+R14+MAX(S14,0)*0.2 -> 566987.69 | U14: =(D14+E14)-(M14+N14) -> -86459.481 | V14: =P14-G14 -> 3311.74 | W14: =J14-S14 -> -10454.596 | X14: =K14-T14 -> 227183.26 | Y14: =Y13+W14 -> 221722.19
A15: 10 | B15: 2036 | C15: Retired + PhD | D15: =ASSUMPTIONS!B28*(1+ASSUMPTIONS!B29)^2+ASSUMPTIONS!B62 -> 93071.555 | E15: =ASSUMPTIONS!B43*12*(1+ASSUMPTIONS!B44)^2+ASSUMPTIONS!B52*12+ASSUMPTIONS!B53 -> 67910.097 | F15: =MAX((D15-E15)*(ASSUMPTIONS!B81+ASSUMPTIONS!B84),0) -> 4780.677 | G15: =ASSUMPTIONS!B35*(1+ASSUMPTIONS!B38)^2 -> 193.0838 | H15: =ASSUMPTIONS!B85*12*(1+ASSUMPTIONS!B86)^10 -> 38605.127 | I15: =ASSUMPTIONS!B77*12 -> 0 | J15: =D15+E15-F15-G15-H15-I15 -> 117402.77 | K15: =K14*(1+ASSUMPTIONS!B74)+I15+MAX(J15,0)*0.2 -> 873243.47 | L15: Research Scientist | M15: =ASSUMPTIONS!B64*(1+ASSUMPTIONS!B66)^3 -> 247470.08 | N15: =ASSUMPTIONS!B43*12*(1+ASSUMPTIONS!B44)^8 -> 8268.6548 | O15: =MAX((M15-N15)*(ASSUMPTIONS!B83+ASSUMPTIONS!B84),0) -> 74152.442 | P15: =ASSUMPTIONS!C36*(1+ASSUMPTIONS!C37)^3 -> 3779.136 | Q15: =ASSUMPTIONS!B85*12*(1+ASSUMPTIONS!B86)^10 -> 38605.127 | R15: =ASSUMPTIONS!B76*12 -> 6000 | S15: =M15+N15-O15-P15-Q15-R15 -> 133202.03 | T15: =T14*(1+ASSUMPTIONS!B74)+R15+MAX(S15,0)*0.2 -> 639317.23 | U15: =(D15+E15)-(M15+N15) -> -94757.082 | V15: =P15-G15 -> 3586.0522 | W15: =J15-S15 -> -15799.265 | X15: =K15-T15 -> 233926.24 | Y15: =Y14+W15 -> 205922.93
A16: 11 | B16: 2037 | C16: Retired + PhD | D16: =ASSUMPTIONS!B28*(1+ASSUMPTIONS!B29)^3+ASSUMPTIONS!B62 -> 94361.559 | E16: =ASSUMPTIONS!B43*12*(1+ASSUMPTIONS!B44)^3+ASSUMPTIONS!B52*12+ASSUMPTIONS!B53 -> 68106.268 | F16: =MAX((D16-E16)*(ASSUMPTIONS!B81+ASSUMPTIONS!B84),0) -> 4988.5052 | G16: =ASSUMPTIONS!B35*(1+ASSUMPTIONS!B38)^3 -> 198.87631 | H16: =ASSUMPTIONS!B85*12*(1+ASSUMPTIONS!B86)^11 -> 39763.281 | I16: =ASSUMPTIONS!B77*12 -> 0 | J16: =D16+E16-F16-G16-H16-I16 -> 117517.16 | K16: =K15*(1+ASSUMPTIONS!B74)+I16+MAX(J16,0)*0.2 -> 957873.95 | L16: Research Scientist | M16: =ASSUMPTIONS!B64*(1+ASSUMPTIONS!B66)^4 -> 257368.88 | N16: =ASSUMPTIONS!B43*12*(1+ASSUMPTIONS!B44)^9 -> 8500.1772 | O16: =MAX((M16-N16)*(ASSUMPTIONS!B83+ASSUMPTIONS!B84),0) -> 77149.299 | P16: =ASSUMPTIONS!C36*(1+ASSUMPTIONS!C37)^4 -> 4081.4669 | Q16: =ASSUMPTIONS!B85*12*(1+ASSUMPTIONS!B86)^11 -> 39763.281 | R16: =ASSUMPTIONS!B76*12 -> 6000 | S16: =M16+N16-O16-P16-Q16-R16 -> 138875.01 | T16: =T15*(1+ASSUMPTIONS!B74)+R16+MAX(S16,0)*0.2 -> 717844.44 | U16: =(D16+E16)-(M16+N16) -> -103401.23 | V16: =P16-G16 -> 3882.5906 | W16: =J16-S16 -> -21357.849 | X16: =K16-T16 -> 240029.5 | Y16: =Y15+W16 -> 184565.08
A17: 12 | B17: 2038 | C17: Retired + PhD | D17: =ASSUMPTIONS!B28*(1+ASSUMPTIONS!B29)^4+ASSUMPTIONS!B62 -> 95687.682 | E17: =ASSUMPTIONS!B43*12*(1+ASSUMPTIONS!B44)^4 -> 7403.9317 | F17: =MAX((D17-E17)*(ASSUMPTIONS!B81+ASSUMPTIONS!B84),0) -> 16773.913 | G17: =ASSUMPTIONS!B35*(1+ASSUMPTIONS!B38)^4 -> 204.8426 | H17: =ASSUMPTIONS!B85*12*(1+ASSUMPTIONS!B86)^12 -> 40956.179 | I17: =ASSUMPTIONS!B77*12 -> 0 | J17: =D17+E17-F17-G17-H17-I17 -> 45156.68 | K17: =K16*(1+ASSUMPTIONS!B74)+I17+MAX(J17,0)*0.2 -> 1033956.5 | L17: Research Scientist | M17: =ASSUMPTIONS!B64*(1+ASSUMPTIONS!B66)^5 -> 267663.64 | N17: =ASSUMPTIONS!B43*12*(1+ASSUMPTIONS!B44)^10 -> 8738.1821 | O17: =MAX((M17-N17)*(ASSUMPTIONS!B83+ASSUMPTIONS!B84),0) -> 80266.891 | P17: =ASSUMPTIONS!C36*(1+ASSUMPTIONS!C37)^5 -> 4407.9842 | Q17: =ASSUMPTIONS!B85*12*(1+ASSUMPTIONS!B86)^12 -> 40956.179 | R17: =ASSUMPTIONS!B76*12 -> 6000 | S17: =M17+N17-O17-P17-Q17-R17 -> 144770.77 | T17: =T16*(1+ASSUMPTIONS!B74)+R17+MAX(S17,0)*0.2 -> 803047.71 | U17: =(D17+E17)-(M17+N17) -> -173310.21 | V17: =P17-G17 -> 4203.1416 | W17: =J17-S17 -> -99614.086 | X17: =K17-T17 -> 230908.75 | Y17: =Y16+W17 -> 84950.99
A18: 13 | B18: 2039 | C18: Retired + PhD | D18: =ASSUMPTIONS!B28*(1+ASSUMPTIONS!B29)^5+ASSUMPTIONS!B62 -> 97050.938 | E18: =ASSUMPTIONS!B43*12*(1+ASSUMPTIONS!B44)^5 -> 7611.2418 | F18: =MAX((D18-E18)*(ASSUMPTIONS!B81+ASSUMPTIONS!B84),0) -> 16993.542 | G18: =ASSUMPTIONS!B35*(1+ASSUMPTIONS!B38)^5 -> 210.98788 | H18: =ASSUMPTIONS!B85*12*(1+ASSUMPTIONS!B86)^13 -> 42184.864 | I18: =ASSUMPTIONS!B77*12 -> 0 | J18: =D18+E18-F18-G18-H18-I18 -> 45272.785 | K18: =K17*(1+ASSUMPTIONS!B74)+I18+MAX(J18,0)*0.2 -> 1115388 | L18: Research Scientist | M18: =ASSUMPTIONS!B64*(1+ASSUMPTIONS!B66)^6 -> 278370.18 | N18: =ASSUMPTIONS!B43*12*(1+ASSUMPTIONS!B44)^11 -> 8982.8512 | O18: =MAX((M18-N18)*(ASSUMPTIONS!B83+ASSUMPTIONS!B84),0) -> 83510.073 | P18: =ASSUMPTIONS!C36*(1+ASSUMPTIONS!C37)^6 -> 4760.623 | Q18: =ASSUMPTIONS!B85*12*(1+ASSUMPTIONS!B86)^13 -> 42184.864 | R18: =ASSUMPTIONS!B76*12 -> 6000 | S18: =M18+N18-O18-P18-Q18-R18 -> 150897.47 | T18: =T17*(1+ASSUMPTIONS!B74)+R18+MAX(S18,0)*0.2 -> 895440.54 | U18: =(D18+E18)-(M18+N18) -> -182690.86 | V18: =P18-G18 -> 4549.6351 | W18: =J18-S18 -> -105624.69 | X18: =K18-T18 -> 219947.43 | Y18: =Y17+W18 -> -20673.7
A19: 14 | B19: 2040 | C19: Retired + Res. Scientist | D19: =ASSUMPTIONS!B28*(1+ASSUMPTIONS!B29)^6+ASSUMPTIONS!B64*(1+ASSUMPTIONS!B66)^0 -> 271452.36 | E19: =ASSUMPTIONS!B43*12*(1+ASSUMPTIONS!B44)^6 -> 7824.3566 | F19: =MAX((D19-E19)*(ASSUMPTIONS!B83+ASSUMPTIONS!B84),0) -> 81724.682 | G19: =ASSUMPTIONS!B35*(1+ASSUMPTIONS!B38)^6 -> 217.31752 | H19: =ASSUMPTIONS!B85*12*(1+ASSUMPTIONS!B86)^14 -> 43450.41 | I19: =ASSUMPTIONS!B76*12 -> 6000 | J19: =D19+E19-F19-G19-H19-I19 -> 147884.31 | K19: =K18*(1+ASSUMPTIONS!B74)+I19+MAX(J19,0)*0.2 -> 1229042 | L19: Research Scientist | M19: =ASSUMPTIONS!B64*(1+ASSUMPTIONS!B66)^7 -> 289504.99 | N19: =ASSUMPTIONS!B43*12*(1+ASSUMPTIONS!B44)^12 -> 9234.3711 | O19: =MAX((M19-N19)*(ASSUMPTIONS!B83+ASSUMPTIONS!B84),0) -> 86883.892 | P19: =ASSUMPTIONS!C36*(1+ASSUMPTIONS!C37)^7 -> 5141.4728 | Q19: =ASSUMPTIONS!B85*12*(1+ASSUMPTIONS!B86)^14 -> 43450.41 | R19: =ASSUMPTIONS!B76*12 -> 6000 | S19: =M19+N19-O19-P19-Q19-R19 -> 157263.59 | T19: =T18*(1+ASSUMPTIONS!B74)+R19+MAX(S19,0)*0.2 -> 995574.1 | U19: =(D19+E19)-(M19+N19) -> -19462.642 | V19: =P19-G19 -> 4924.1553 | W19: =J19-S19 -> -9379.2768 | X19: =K19-T19 -> 233467.89 | Y19: =Y18+W19 -> -30052.977
A20: 15 | B20: 2041 | C20: Retired + Res. Scientist | D20: =ASSUMPTIONS!B28*(1+ASSUMPTIONS!B29)^7+ASSUMPTIONS!B64*(1+ASSUMPTIONS!B66)^1 -> 281693.03 | E20: =ASSUMPTIONS!B43*12*(1+ASSUMPTIONS!B44)^7 -> 8043.4386 | F20: =MAX((D20-E20)*(ASSUMPTIONS!B83+ASSUMPTIONS!B84),0) -> 84831.373 | G20: =ASSUMPTIONS!B35*(1+ASSUMPTIONS!B38)^7 -> 223.83704 | H20: =ASSUMPTIONS!B85*12*(1+ASSUMPTIONS!B86)^15 -> 44753.923 | I20: =ASSUMPTIONS!B76*12 -> 6000 | J20: =D20+E20-F20-G20-H20-I20 -> 153927.34 | K20: =K19*(1+ASSUMPTIONS!B74)+I20+MAX(J20,0)*0.2 -> 1351860.4 | L20: Research Scientist | M20: =ASSUMPTIONS!B64*(1+ASSUMPTIONS!B66)^8 -> 301085.19 | N20: =ASSUMPTIONS!B43*12*(1+ASSUMPTIONS!B44)^13 -> 9492.9335 | O20: =MAX((M20-N20)*(ASSUMPTIONS!B83+ASSUMPTIONS!B84),0) -> 90393.6 | P20: =ASSUMPTIONS!C36*(1+ASSUMPTIONS!C37)^8 -> 5552.7906 | Q20: =ASSUMPTIONS!B85*12*(1+ASSUMPTIONS!B86)^15 -> 44753.923 | R20: =ASSUMPTIONS!B76*12 -> 6000 | S20: =M20+N20-O20-P20-Q20-R20 -> 163877.81 | T20: =T19*(1+ASSUMPTIONS!B74)+R20+MAX(S20,0)*0.2 -> 1104039.8 | U20: =(D20+E20)-(M20+N20) -> -20841.656 | V20: =P20-G20 -> 5328.9536 | W20: =J20-S20 -> -9950.4759 | X20: =K20-T20 -> 247820.55 | Y20: =Y19+W20 -> -40003.453
A21: 16 | B21: 2042 | C21: Retired + Res. Scientist | D21: =ASSUMPTIONS!B28*(1+ASSUMPTIONS!B29)^8+ASSUMPTIONS!B64*(1+ASSUMPTIONS!B66)^2 -> 292326.03 | E21: =ASSUMPTIONS!B43*12*(1+ASSUMPTIONS!B44)^8 -> 8268.6548 | F21: =MAX((D21-E21)*(ASSUMPTIONS!B83+ASSUMPTIONS!B84),0) -> 88057.788 | G21: =ASSUMPTIONS!B35*(1+ASSUMPTIONS!B38)^8 -> 230.55215 | H21: =ASSUMPTIONS!B85*12*(1+ASSUMPTIONS!B86)^16 -> 46096.54 | I21: =ASSUMPTIONS!B76*12 -> 6000 | J21: =D21+E21-F21-G21-H21-I21 -> 160209.81 | K21: =K20*(1+ASSUMPTIONS!B74)+I21+MAX(J21,0)*0.2 -> 1484532.6 | L21: Research Scientist | M21: =ASSUMPTIONS!B64*(1+ASSUMPTIONS!B66)^9 -> 313128.6 | N21: =ASSUMPTIONS!B43*12*(1+ASSUMPTIONS!B44)^14 -> 9758.7356 | O21: =MAX((M21-N21)*(ASSUMPTIONS!B83+ASSUMPTIONS!B84),0) -> 94044.658 | P21: =ASSUMPTIONS!C36*(1+ASSUMPTIONS!C37)^9 -> 5997.0139 | Q21: =ASSUMPTIONS!B85*12*(1+ASSUMPTIONS!B86)^16 -> 46096.54 | R21: =ASSUMPTIONS!B76*12 -> 6000 | S21: =M21+N21-O21-P21-Q21-R21 -> 170749.12 | T21: =T20*(1+ASSUMPTIONS!B74)+R21+MAX(S21,0)*0.2 -> 1221472.5 | U21: =(D21+E21)-(M21+N21) -> -22292.645 | V21: =P21-G21 -> 5766.4617 | W21: =J21-S21 -> -10539.313 | X21: =K21-T21 -> 263060.12 | Y21: =Y20+W21 -> -50542.766
A22: 17 | B22: 2043 | C22: Retired + Res. Scientist | D22: =ASSUMPTIONS!B28*(1+ASSUMPTIONS!B29)^9+ASSUMPTIONS!B64*(1+ASSUMPTIONS!B66)^3 -> 303366.59 | E22: =ASSUMPTIONS!B43*12*(1+ASSUMPTIONS!B44)^9 -> 8500.1772 | F22: =MAX((D22-E22)*(ASSUMPTIONS!B83+ASSUMPTIONS!B84),0) -> 91408.587 | G22: =ASSUMPTIONS!B35*(1+ASSUMPTIONS!B38)^9 -> 237.46872 | H22: =ASSUMPTIONS!B85*12*(1+ASSUMPTIONS!B86)^17 -> 47479.437 | I22: =ASSUMPTIONS!B76*12 -> 6000 | J22: =D22+E22-F22-G22-H22-I22 -> 166741.27 | K22: =K21*(1+ASSUMPTIONS!B74)+I22+MAX(J22,0)*0.2 -> 1627798.1 | L22: Research Scientist | M22: =ASSUMPTIONS!B64*(1+ASSUMPTIONS!B66)^10 -> 325653.74 | N22: =ASSUMPTIONS!B43*12*(1+ASSUMPTIONS!B44)^15 -> 10031.98 | O22: =MAX((M22-N22)*(ASSUMPTIONS!B83+ASSUMPTIONS!B84),0) -> 97842.746 | P22: =ASSUMPTIONS!C36*(1+ASSUMPTIONS!C37)^10 -> 6476.775 | Q22: =ASSUMPTIONS!B85*12*(1+ASSUMPTIONS!B86)^17 -> 47479.437 | R22: =ASSUMPTIONS!B76*12 -> 6000 | S22: =M22+N22-O22-P22-Q22-R22 -> 177886.76 | T22: =T21*(1+ASSUMPTIONS!B74)+R22+MAX(S22,0)*0.2 -> 1348552.9 | U22: =(D22+E22)-(M22+N22) -> -23818.958 | V22: =P22-G22 -> 6239.3063 | W22: =J22-S22 -> -11145.493 | X22: =K22-T22 -> 279245.23 | Y22: =Y21+W22 -> -61688.258
A23: 18 | B23: 2044 | C23: Retired + Res. Scientist | D23: =ASSUMPTIONS!B28*(1+ASSUMPTIONS!B29)^10+ASSUMPTIONS!B64*(1+ASSUMPTIONS!B66)^4 -> 314830.49 | E23: =ASSUMPTIONS!B43*12*(1+ASSUMPTIONS!B44)^10 -> 8738.1821 | F23: =MAX((D23-E23)*(ASSUMPTIONS!B83+ASSUMPTIONS!B84),0) -> 94888.616 | G23: =ASSUMPTIONS!B35*(1+ASSUMPTIONS!B38)^10 -> 244.59278 | H23: =ASSUMPTIONS!B85*12*(1+ASSUMPTIONS!B86)^18 -> 48903.82 | I23: =ASSUMPTIONS!B76*12 -> 6000 | J23: =D23+E23-F23-G23-H23-I23 -> 173531.65 | K23: =K22*(1+ASSUMPTIONS!B74)+I23+MAX(J23,0)*0.2 -> 1782450.3 | L23: Research Scientist | M23: =ASSUMPTIONS!B64*(1+ASSUMPTIONS!B66)^11 -> 338679.89 | N23: =ASSUMPTIONS!B43*12*(1+ASSUMPTIONS!B44)^16 -> 10312.876 | O23: =MAX((M23-N23)*(ASSUMPTIONS!B83+ASSUMPTIONS!B84),0) -> 101793.78 | P23: =ASSUMPTIONS!C36*(1+ASSUMPTIONS!C37)^11 -> 6994.917 | Q23: =ASSUMPTIONS!B85*12*(1+ASSUMPTIONS!B86)^18 -> 48903.82 | R23: =ASSUMPTIONS!B76*12 -> 6000 | S23: =M23+N23-O23-P23-Q23-R23 -> 185300.26 | T23: =T22*(1+ASSUMPTIONS!B74)+R23+MAX(S23,0)*0.2 -> 1486011.6 | U23: =(D23+E23)-(M23+N23) -> -25424.093 | V23: =P23-G23 -> 6750.3242 | W23: =J23-S23 -> -11768.61 | X23: =K23-T23 -> 296438.68 | Y23: =Y22+W23 -> -73456.868
A24: 19 | B24: 2045 | C24: Retired + Res. Scientist | D24: =ASSUMPTIONS!B28*(1+ASSUMPTIONS!B29)^11+ASSUMPTIONS!B64*(1+ASSUMPTIONS!B66)^5 -> 326734.17 | E24: =ASSUMPTIONS!B43*12*(1+ASSUMPTIONS!B44)^11 -> 8982.8512 | F24: =MAX((D24-E24)*(ASSUMPTIONS!B83+ASSUMPTIONS!B84),0) -> 98502.91 | G24: =ASSUMPTIONS!B35*(1+ASSUMPTIONS!B38)^11 -> 251.93056 | H24: =ASSUMPTIONS!B85*12*(1+ASSUMPTIONS!B86)^19 -> 50370.934 | I24: =ASSUMPTIONS!B76*12 -> 6000 | J24: =D24+E24-F24-G24-H24-I24 -> 180591.25 | K24: =K23*(1+ASSUMPTIONS!B74)+I24+MAX(J24,0)*0.2 -> 1949340.1 | L24: Research Scientist | M24: =ASSUMPTIONS!B64*(1+ASSUMPTIONS!B66)^12 -> 352227.09 | N24: =ASSUMPTIONS!B43*12*(1+ASSUMPTIONS!B44)^17 -> 10601.636 | O24: =MAX((M24-N24)*(ASSUMPTIONS!B83+ASSUMPTIONS!B84),0) -> 105903.89 | P24: =ASSUMPTIONS!C36*(1+ASSUMPTIONS!C37)^12 -> 7554.5104 | Q24: =ASSUMPTIONS!B85*12*(1+ASSUMPTIONS!B86)^19 -> 50370.934 | R24: =ASSUMPTIONS!B76*12 -> 6000 | S24: =M24+N24-O24-P24-Q24-R24 -> 192999.39 | T24: =T23*(1+ASSUMPTIONS!B74)+R24+MAX(S24,0)*0.2 -> 1634632.3 | U24: =(D24+E24)-(M24+N24) -> -27111.699 | V24: =P24-G24 -> 7302.5798 | W24: =J24-S24 -> -12408.139 | X24: =K24-T24 -> 314707.76 | Y24: =Y23+W24 -> -85865.007
A25: 20 | B25: 2046 | C25: Retired + Res. Scientist | D25: =ASSUMPTIONS!B28*(1+ASSUMPTIONS!B29)^12+ASSUMPTIONS!B64*(1+ASSUMPTIONS!B66)^6 -> 339094.69 | E25: =ASSUMPTIONS!B43*12*(1+ASSUMPTIONS!B44)^12 -> 9234.3711 | F25: =MAX((D25-E25)*(ASSUMPTIONS!B83+ASSUMPTIONS!B84),0) -> 102256.7 | G25: =ASSUMPTIONS!B35*(1+ASSUMPTIONS!B38)^12 -> 259.48848 | H25: =ASSUMPTIONS!B85*12*(1+ASSUMPTIONS!B86)^20 -> 51882.062 | I25: =ASSUMPTIONS!B76*12 -> 6000 | J25: =D25+E25-F25-G25-H25-I25 -> 187930.81 | K25: =K24*(1+ASSUMPTIONS!B74)+I25+MAX(J25,0)*0.2 -> 2129380.1 | L25: Research Scientist | M25: =ASSUMPTIONS!B64*(1+ASSUMPTIONS!B66)^13 -> 366316.17 | N25: =ASSUMPTIONS!B43*12*(1+ASSUMPTIONS!B44)^18 -> 10898.482 | O25: =MAX((M25-N25)*(ASSUMPTIONS!B83+ASSUMPTIONS!B84),0) -> 110179.48 | P25: =ASSUMPTIONS!C36*(1+ASSUMPTIONS!C37)^13 -> 8158.8712 | Q25: =ASSUMPTIONS!B85*12*(1+ASSUMPTIONS!B86)^20 -> 51882.062 | R25: =ASSUMPTIONS!B76*12 -> 6000 | S25: =M25+N25-O25-P25-Q25-R25 -> 200994.24 | T25: =T24*(1+ASSUMPTIONS!B74)+R25+MAX(S25,0)*0.2 -> 1795255.4 | U25: =(D25+E25)-(M25+N25) -> -28885.588 | V25: =P25-G25 -> 7899.3827 | W25: =J25-S25 -> -13063.422 | X25: =K25-T25 -> 334124.61 | Y25: =Y24+W25 -> -98928.429
A26: 21 | B26: 2047 | C26: Retired + Res. Scientist | D26: =ASSUMPTIONS!B28*(1+ASSUMPTIONS!B29)^13+ASSUMPTIONS!B64*(1+ASSUMPTIONS!B66)^7 -> 351929.79 | E26: =ASSUMPTIONS!B43*12*(1+ASSUMPTIONS!B44)^13 -> 9492.9335 | F26: =MAX((D26-E26)*(ASSUMPTIONS!B83+ASSUMPTIONS!B84),0) -> 106155.42 | G26: =ASSUMPTIONS!B35*(1+ASSUMPTIONS!B38)^13 -> 267.27314 | H26: =ASSUMPTIONS!B85*12*(1+ASSUMPTIONS!B86)^21 -> 53438.524 | I26: =ASSUMPTIONS!B76*12 -> 6000 | J26: =D26+E26-F26-G26-H26-I26 -> 195561.5 | K26: =K25*(1+ASSUMPTIONS!B74)+I26+MAX(J26,0)*0.2 -> 2323549 | L26: Research Scientist | M26: =ASSUMPTIONS!B64*(1+ASSUMPTIONS!B66)^14 -> 380968.82 | N26: =ASSUMPTIONS!B43*12*(1+ASSUMPTIONS!B44)^19 -> 11203.639 | O26: =MAX((M26-N26)*(ASSUMPTIONS!B83+ASSUMPTIONS!B84),0) -> 114627.21 | P26: =ASSUMPTIONS!C36*(1+ASSUMPTIONS!C37)^14 -> 8811.5809 | Q26: =ASSUMPTIONS!B85*12*(1+ASSUMPTIONS!B86)^21 -> 53438.524 | R26: =ASSUMPTIONS!B76*12 -> 6000 | S26: =M26+N26-O26-P26-Q26-R26 -> 209295.15 | T26: =T25*(1+ASSUMPTIONS!B74)+R26+MAX(S26,0)*0.2 -> 1968782.4 | U26: =(D26+E26)-(M26+N26) -> -30749.737 | V26: =P26-G26 -> 8544.3077 | W26: =J26-S26 -> -13733.648 | X26: =K26-T26 -> 354766.61 | Y26: =Y25+W26 -> -112662.08
A27: 22 | B27: 2048 | C27: Retired + Res. Scientist | D27: =ASSUMPTIONS!B28*(1+ASSUMPTIONS!B29)^14+ASSUMPTIONS!B64*(1+ASSUMPTIONS!B66)^8 -> 365257.88 | E27: =ASSUMPTIONS!B43*12*(1+ASSUMPTIONS!B44)^14 -> 9758.7356 | F27: =MAX((D27-E27)*(ASSUMPTIONS!B83+ASSUMPTIONS!B84),0) -> 110204.74 | G27: =ASSUMPTIONS!B35*(1+ASSUMPTIONS!B38)^14 -> 275.29133 | H27: =ASSUMPTIONS!B85*12*(1+ASSUMPTIONS!B86)^22 -> 55041.68 | I27: =ASSUMPTIONS!B76*12 -> 6000 | J27: =D27+E27-F27-G27-H27-I27 -> 203494.91 | K27: =K26*(1+ASSUMPTIONS!B74)+I27+MAX(J27,0)*0.2 -> 2532896.4 | L27: Research Scientist | M27: =ASSUMPTIONS!B64*(1+ASSUMPTIONS!B66)^15 -> 396207.57 | N27: =ASSUMPTIONS!B43*12*(1+ASSUMPTIONS!B44)^20 -> 11517.341 | O27: =MAX((M27-N27)*(ASSUMPTIONS!B83+ASSUMPTIONS!B84),0) -> 119253.97 | P27: =ASSUMPTIONS!C36*(1+ASSUMPTIONS!C37)^15 -> 9516.5073 | Q27: =ASSUMPTIONS!B85*12*(1+ASSUMPTIONS!B86)^22 -> 55041.68 | R27: =ASSUMPTIONS!B76*12 -> 6000 | S27: =M27+N27-O27-P27-Q27-R27 -> 217912.75 | T27: =T26*(1+ASSUMPTIONS!B74)+R27+MAX(S27,0)*0.2 -> 2156179.7 | U27: =(D27+E27)-(M27+N27) -> -32708.295 | V27: =P27-G27 -> 9241.216 | W27: =J27-S27 -> -14417.843 | X27: =K27-T27 -> 376716.7 | Y27: =Y26+W27 -> -127079.92
A28: 23 | B28: 2049 | C28: Retired + Res. Scientist | D28: =ASSUMPTIONS!B28*(1+ASSUMPTIONS!B29)^15+ASSUMPTIONS!B64*(1+ASSUMPTIONS!B66)^9 -> 379098.12 | E28: =ASSUMPTIONS!B43*12*(1+ASSUMPTIONS!B44)^15 -> 10031.98 | F28: =MAX((D28-E28)*(ASSUMPTIONS!B83+ASSUMPTIONS!B84),0) -> 114410.5 | G28: =ASSUMPTIONS!B35*(1+ASSUMPTIONS!B38)^15 -> 283.55007 | H28: =ASSUMPTIONS!B85*12*(1+ASSUMPTIONS!B86)^23 -> 56692.93 | I28: =ASSUMPTIONS!B76*12 -> 6000 | J28: =D28+E28-F28-G28-H28-I28 -> 211743.12 | K28: =K27*(1+ASSUMPTIONS!B74)+I28+MAX(J28,0)*0.2 -> 2758547.7 | L28: Research Scientist | M28: =ASSUMPTIONS!B64*(1+ASSUMPTIONS!B66)^16 -> 412055.87 | N28: =ASSUMPTIONS!B43*12*(1+ASSUMPTIONS!B44)^21 -> 11839.827 | O28: =MAX((M28-N28)*(ASSUMPTIONS!B83+ASSUMPTIONS!B84),0) -> 124066.97 | P28: =ASSUMPTIONS!C36*(1+ASSUMPTIONS!C37)^16 -> 10277.828 | Q28: =ASSUMPTIONS!B85*12*(1+ASSUMPTIONS!B86)^23 -> 56692.93 | R28: =ASSUMPTIONS!B76*12 -> 6000 | S28: =M28+N28-O28-P28-Q28-R28 -> 226857.97 | T28: =T27*(1+ASSUMPTIONS!B74)+R28+MAX(S28,0)*0.2 -> 2358483.8 | U28: =(D28+E28)-(M28+N28) -> -34765.596 | V28: =P28-G28 -> 9994.2779 | W28: =J28-S28 -> -15114.848 | X28: =K28-T28 -> 400063.9 | Y28: =Y27+W28 -> -142194.77
A29: 24 | B29: 2050 | C29: Retired + Res. Scientist | D29: =ASSUMPTIONS!B28*(1+ASSUMPTIONS!B29)^16+ASSUMPTIONS!B64*(1+ASSUMPTIONS!B66)^10 -> 393470.42 | E29: =ASSUMPTIONS!B43*12*(1+ASSUMPTIONS!B44)^16 -> 10312.876 | F29: =MAX((D29-E29)*(ASSUMPTIONS!B83+ASSUMPTIONS!B84),0) -> 118778.84 | G29: =ASSUMPTIONS!B35*(1+ASSUMPTIONS!B38)^16 -> 292.05657 | H29: =ASSUMPTIONS!B85*12*(1+ASSUMPTIONS!B86)^24 -> 58393.718 | I29: =ASSUMPTIONS!B76*12 -> 6000 | J29: =D29+E29-F29-G29-H29-I29 -> 220318.68 | K29: =K28*(1+ASSUMPTIONS!B74)+I29+MAX(J29,0)*0.2 -> 3001709.8 | L29: Research Scientist | M29: =ASSUMPTIONS!B64*(1+ASSUMPTIONS!B66)^17 -> 428538.11 | N29: =ASSUMPTIONS!B43*12*(1+ASSUMPTIONS!B44)^22 -> 12171.342 | O29: =MAX((M29-N29)*(ASSUMPTIONS!B83+ASSUMPTIONS!B84),0) -> 129073.7 | P29: =ASSUMPTIONS!C36*(1+ASSUMPTIONS!C37)^17 -> 11100.054 | Q29: =ASSUMPTIONS!B85*12*(1+ASSUMPTIONS!B86)^24 -> 58393.718 | R29: =ASSUMPTIONS!B76*12 -> 6000 | S29: =M29+N29-O29-P29-Q29-R29 -> 236141.98 | T29: =T28*(1+ASSUMPTIONS!B74)+R29+MAX(S29,0)*0.2 -> 2576806.1 | U29: =(D29+E29)-(M29+N29) -> -36926.16 | V29: =P29-G29 -> 10807.998 | W29: =J29-S29 -> -15823.302 | X29: =K29-T29 -> 424903.71 | Y29: =Y28+W29 -> -158018.07
A30: 25 | B30: 2051 | C30: Retired + Res. Scientist | D30: =ASSUMPTIONS!B28*(1+ASSUMPTIONS!B29)^17+ASSUMPTIONS!B64*(1+ASSUMPTIONS!B66)^11 -> 408395.43 | E30: =ASSUMPTIONS!B43*12*(1+ASSUMPTIONS!B44)^17 -> 10601.636 | F30: =MAX((D30-E30)*(ASSUMPTIONS!B83+ASSUMPTIONS!B84),0) -> 123316.08 | G30: =ASSUMPTIONS!B35*(1+ASSUMPTIONS!B38)^17 -> 300.81827 | H30: =ASSUMPTIONS!B85*12*(1+ASSUMPTIONS!B86)^25 -> 60145.53 | I30: =ASSUMPTIONS!B76*12 -> 6000 | J30: =D30+E30-F30-G30-H30-I30 -> 229234.64 | K30: =K29*(1+ASSUMPTIONS!B74)+I30+MAX(J30,0)*0.2 -> 3263676.4 | L30: Research Scientist | M30: =ASSUMPTIONS!B64*(1+ASSUMPTIONS!B66)^18 -> 445679.63 | N30: =ASSUMPTIONS!B43*12*(1+ASSUMPTIONS!B44)^23 -> 12512.14 | O30: =MAX((M30-N30)*(ASSUMPTIONS!B83+ASSUMPTIONS!B84),0) -> 134281.92 | P30: =ASSUMPTIONS!C36*(1+ASSUMPTIONS!C37)^18 -> 11988.058 | Q30: =ASSUMPTIONS!B85*12*(1+ASSUMPTIONS!B86)^25 -> 60145.53 | R30: =ASSUMPTIONS!B76*12 -> 6000 | S30: =M30+N30-O30-P30-Q30-R30 -> 245776.26 | T30: =T29*(1+ASSUMPTIONS!B74)+R30+MAX(S30,0)*0.2 -> 2812337.8 | U30: =(D30+E30)-(M30+N30) -> -39194.705 | V30: =P30-G30 -> 11687.24 | W30: =J30-S30 -> -16541.618 | X30: =K30-T30 -> 451338.65 | Y30: =Y29+W30 -> -174559.69
A31: 26 | B31: 2052 | C31: Retired + Res. Scientist | D31: =ASSUMPTIONS!B28*(1+ASSUMPTIONS!B29)^18+ASSUMPTIONS!B64*(1+ASSUMPTIONS!B66)^12 -> 423894.66 | E31: =ASSUMPTIONS!B43*12*(1+ASSUMPTIONS!B44)^18 -> 10898.482 | F31: =MAX((D31-E31)*(ASSUMPTIONS!B83+ASSUMPTIONS!B84),0) -> 128028.82 | G31: =ASSUMPTIONS!B35*(1+ASSUMPTIONS!B38)^18 -> 309.84282 | H31: =ASSUMPTIONS!B85*12*(1+ASSUMPTIONS!B86)^26 -> 61949.896 | I31: =ASSUMPTIONS!B76*12 -> 6000 | J31: =D31+E31-F31-G31-H31-I31 -> 238504.59 | K31: =K30*(1+ASSUMPTIONS!B74)+I31+MAX(J31,0)*0.2 -> 3545834.7 | L31: Research Scientist | M31: =ASSUMPTIONS!B64*(1+ASSUMPTIONS!B66)^19 -> 463506.82 | N31: =ASSUMPTIONS!B43*12*(1+ASSUMPTIONS!B44)^24 -> 12862.48 | O31: =MAX((M31-N31)*(ASSUMPTIONS!B83+ASSUMPTIONS!B84),0) -> 139699.75 | P31: =ASSUMPTIONS!C36*(1+ASSUMPTIONS!C37)^19 -> 12947.103 | Q31: =ASSUMPTIONS!B85*12*(1+ASSUMPTIONS!B86)^26 -> 61949.896 | R31: =ASSUMPTIONS!B76*12 -> 6000 | S31: =M31+N31-O31-P31-Q31-R31 -> 255772.55 | T31: =T30*(1+ASSUMPTIONS!B74)+R31+MAX(S31,0)*0.2 -> 3066355.9 | U31: =(D31+E31)-(M31+N31) -> -41576.154 | V31: =P31-G31 -> 12637.26 | W31: =J31-S31 -> -17267.964 | X31: =K31-T31 -> 479478.76 | Y31: =Y30+W31 -> -191827.65
A32: 27 | B32: 2053 | C32: Retired + Res. Scientist | D32: =ASSUMPTIONS!B28*(1+ASSUMPTIONS!B29)^19+ASSUMPTIONS!B64*(1+ASSUMPTIONS!B66)^13 -> 439990.44 | E32: =ASSUMPTIONS!B43*12*(1+ASSUMPTIONS!B44)^19 -> 11203.639 | F32: =MAX((D32-E32)*(ASSUMPTIONS!B83+ASSUMPTIONS!B84),0) -> 132923.91 | G32: =ASSUMPTIONS!B35*(1+ASSUMPTIONS!B38)^19 -> 319.1381 | H32: =ASSUMPTIONS!B85*12*(1+ASSUMPTIONS!B86)^27 -> 63808.393 | I32: =ASSUMPTIONS!B76*12 -> 6000 | J32: =D32+E32-F32-G32-H32-I32 -> 248142.64 | K32: =K31*(1+ASSUMPTIONS!B74)+I32+MAX(J32,0)*0.2 -> 3849671.7 | L32: Research Scientist | M32: =ASSUMPTIONS!B64*(1+ASSUMPTIONS!B66)^20 -> 482047.09 | N32: =ASSUMPTIONS!B43*12*(1+ASSUMPTIONS!B44)^25 -> 13222.629 | O32: =MAX((M32-N32)*(ASSUMPTIONS!B83+ASSUMPTIONS!B84),0) -> 145335.58 | P32: =ASSUMPTIONS!C36*(1+ASSUMPTIONS!C37)^20 -> 13982.871 | Q32: =ASSUMPTIONS!B85*12*(1+ASSUMPTIONS!B86)^27 -> 63808.393 | R32: =ASSUMPTIONS!B76*12 -> 6000 | S32: =M32+N32-O32-P32-Q32-R32 -> 266142.87 | T32: =T31*(1+ASSUMPTIONS!B74)+R32+MAX(S32,0)*0.2 -> 3340229.4 | U32: =(D32+E32)-(M32+N32) -> -44075.643 | V32: =P32-G32 -> 13663.733 | W32: =J32-S32 -> -18000.234 | X32: =K32-T32 -> 509442.23 | Y32: =Y31+W32 -> -209827.89
A33: 28 | B33: 2054 | C33: Retired + Res. Scientist | D33: =ASSUMPTIONS!B28*(1+ASSUMPTIONS!B29)^20+ASSUMPTIONS!B64*(1+ASSUMPTIONS!B66)^14 -> 456705.96 | E33: =ASSUMPTIONS!B43*12*(1+ASSUMPTIONS!B44)^20 -> 11517.341 | F33: =MAX((D33-E33)*(ASSUMPTIONS!B83+ASSUMPTIONS!B84),0) -> 138008.47 | G33: =ASSUMPTIONS!B35*(1+ASSUMPTIONS!B38)^20 -> 328.71224 | H33: =ASSUMPTIONS!B85*12*(1+ASSUMPTIONS!B86)^28 -> 65722.644 | I33: =ASSUMPTIONS!B76*12 -> 6000 | J33: =D33+E33-F33-G33-H33-I33 -> 258163.48 | K33: =K32*(1+ASSUMPTIONS!B74)+I33+MAX(J33,0)*0.2 -> 4176781.4 | L33: Research Scientist | M33: =ASSUMPTIONS!B64*(1+ASSUMPTIONS!B66)^21 -> 501328.98 | N33: =ASSUMPTIONS!B43*12*(1+ASSUMPTIONS!B44)^26 -> 13592.863 | O33: =MAX((M33-N33)*(ASSUMPTIONS!B83+ASSUMPTIONS!B84),0) -> 151198.19 | P33: =ASSUMPTIONS!C36*(1+ASSUMPTIONS!C37)^21 -> 15101.501 | Q33: =ASSUMPTIONS!B85*12*(1+ASSUMPTIONS!B86)^28 -> 65722.644 | R33: =ASSUMPTIONS!B76*12 -> 6000 | S33: =M33+N33-O33-P33-Q33-R33 -> 276899.5 | T33: =T32*(1+ASSUMPTIONS!B74)+R33+MAX(S33,0)*0.2 -> 3635425.4 | U33: =(D33+E33)-(M33+N33) -> -46698.532 | V33: =P33-G33 -> 14772.789 | W33: =J33-S33 -> -18736.021 | X33: =K33-T33 -> 541355.98 | Y33: =Y32+W33 -> -228563.91
A34: 29 | B34: 2055 | C34: Retired + Res. Scientist | D34: =ASSUMPTIONS!B28*(1+ASSUMPTIONS!B29)^21+ASSUMPTIONS!B64*(1+ASSUMPTIONS!B66)^15 -> 474065.36 | E34: =ASSUMPTIONS!B43*12*(1+ASSUMPTIONS!B44)^21 -> 11839.827 | F34: =MAX((D34-E34)*(ASSUMPTIONS!B83+ASSUMPTIONS!B84),0) -> 143289.91 | G34: =ASSUMPTIONS!B35*(1+ASSUMPTIONS!B38)^21 -> 338.57361 | H34: =ASSUMPTIONS!B85*12*(1+ASSUMPTIONS!B86)^29 -> 67694.324 | I34: =ASSUMPTIONS!B76*12 -> 6000 | J34: =D34+E34-F34-G34-H34-I34 -> 268582.37 | K34: =K33*(1+ASSUMPTIONS!B74)+I34+MAX(J34,0)*0.2 -> 4528872.5 | L34: Research Scientist | M34: =ASSUMPTIONS!B64*(1+ASSUMPTIONS!B66)^22 -> 521382.13 | N34: =ASSUMPTIONS!B43*12*(1+ASSUMPTIONS!B44)^27 -> 13973.463 | O34: =MAX((M34-N34)*(ASSUMPTIONS!B83+ASSUMPTIONS!B84),0) -> 157296.69 | P34: =ASSUMPTIONS!C36*(1+ASSUMPTIONS!C37)^22 -> 16309.621 | Q34: =ASSUMPTIONS!B85*12*(1+ASSUMPTIONS!B86)^29 -> 67694.324 | R34: =ASSUMPTIONS!B76*12 -> 6000 | S34: =M34+N34-O34-P34-Q34-R34 -> 288054.96 | T34: =T33*(1+ASSUMPTIONS!B74)+R34+MAX(S34,0)*0.2 -> 3953516.2 | U34: =(D34+E34)-(M34+N34) -> -49450.412 | V34: =P34-G34 -> 15971.048 | W34: =J34-S34 -> -19472.591 | X34: =K34-T34 -> 575356.38 | Y34: =Y33+W34 -> -248036.5
A35: 30 | B35: 2056 | C35: Retired + Res. Scientist | D35: =ASSUMPTIONS!B28*(1+ASSUMPTIONS!B29)^22+ASSUMPTIONS!B64*(1+ASSUMPTIONS!B66)^16 -> 492093.68 | E35: =ASSUMPTIONS!B43*12*(1+ASSUMPTIONS!B44)^22 -> 12171.342 | F35: =MAX((D35-E35)*(ASSUMPTIONS!B83+ASSUMPTIONS!B84),0) -> 148775.92 | G35: =ASSUMPTIONS!B35*(1+ASSUMPTIONS!B38)^22 -> 348.73082 | H35: =ASSUMPTIONS!B85*12*(1+ASSUMPTIONS!B86)^30 -> 69725.153 | I35: =ASSUMPTIONS!B76*12 -> 6000 | J35: =D35+E35-F35-G35-H35-I35 -> 279415.21 | K35: =K34*(1+ASSUMPTIONS!B74)+I35+MAX(J35,0)*0.2 -> 4907776.7 | L35: Research Scientist | M35: =ASSUMPTIONS!B64*(1+ASSUMPTIONS!B66)^23 -> 542237.42 | N35: =ASSUMPTIONS!B43*12*(1+ASSUMPTIONS!B44)^28 -> 14364.72 | O35: =MAX((M35-N35)*(ASSUMPTIONS!B83+ASSUMPTIONS!B84),0) -> 163640.54 | P35: =ASSUMPTIONS!C36*(1+ASSUMPTIONS!C37)^23 -> 17614.391 | Q35: =ASSUMPTIONS!B85*12*(1+ASSUMPTIONS!B86)^30 -> 69725.153 | R35: =ASSUMPTIONS!B76*12 -> 6000 | S35: =M35+N35-O35-P35-Q35-R35 -> 299622.06 | T35: =T34*(1+ASSUMPTIONS!B74)+R35+MAX(S35,0)*0.2 -> 4296186.7 | U35: =(D35+E35)-(M35+N35) -> -52337.119 | V35: =P35-G35 -> 17265.66 | W35: =J35-S35 -> -20206.846 | X35: =K35-T35 -> 611589.96 | Y35: =Y34+W35 -> -268243.35
A37: 30-YEAR TOTALS & KEY METRICS
A38: Total Gross Income | D38: =SUM(D5:D35) -> 7817512.9 | M38: =SUM(M5:M35) -> 9006893.3 | U38: =D38-M38 -> -1189380.4
A39: Total Tax-Free Income | E39: =SUM(E5:E35) -> 760546.71 | N39: =SUM(N5:N35) -> 490639 | U39: =E39-N39 -> 269907.7
A40: Total Taxes Paid | F40: =SUM(F5:F35) -> 2078461 | O40: =SUM(O5:O35) -> 2619966 | U40: =O40-F40 -> 541504.98
A41: Total Healthcare Costs | G41: =SUM(G5:G35) -> 5769.9248 | P41: =SUM(P5:P35) -> 210294.28 | V41: =P41-G41 -> 204524.35
...

Sheet CHARTS
A1: CHART 1 — Investment Portfolio Growth (Path A vs Path B)
A2: Shows total invested assets accumulating over 30 yrs. Both paths start from same base (~$204K). Path A is green, Path B is orange. Path A ends ~$453K higher due to pension supplementing investments.
A19: CHART 2 — Annual Net Cash Flow (Path A vs Path B)
A20: How much money is left each year after taxes, healthcare, expenses, and savings contributions. The dip in Path A around 2035-2039 is the PhD years — pension + stipend is tight but survivable.
A37: CHART 3 — Cumulative Cash Flow Advantage (SINGLE series by design)
A38: This chart shows Path A's RUNNING LEAD over Path B in total cash flow. Positive = Path A is cumulatively ahead. Negative = Path B has overtaken Path A. It uses ONE line (the DIFFERENCE) so you can instantly see when the crossover happens (~2038). It is NOT a bug that only one line appears — this is a delta chart, not a comparison chart.
A55: CHART 4 — Annual Healthcare Costs (TRICARE vs Civilian)
A56: TRICARE retiree costs ~$182/yr and grows slowly. Civilian insurance starts ~$3,000/yr and grows 8%/yr. The gap widens dramatically over time — 30-year total difference exceeds $200K.
A73: CHART 5 — Income Breakdown: Gross vs Tax-Free for Both Paths
A74: Path A Gross + Tax-Free lines vs Path B Gross + Tax-Free. Note how tax-free income (BAH, VA disability, GI Bill) is a major advantage for Path A especially during active duty.

Sheet GOALS
A1: Name:
A2: FINANCIAL GOALS
A3: Short-Term Goals: less than 2 years
A5: Medium-Term Goals: between 2-5 years
A7: Long-Term Goals: over 5 years

Sheet INCOME
A1: INCOME
A2: City or Zip Code | B2: CURRENT LOCATION | C2: POTENTIAL LOCATION | D2: POTENTIAL LOCATION
A4: SERVICE MEMBER MONTHLY INCOME
A5: ENTITLEMENTS | B5: CURRENT | C5: PROJECTED - Computer Science Job | D5: PROJECTED - Grad School
A6: Monthly Base Pay | B6: 5591.66 | C6: 9803.15 | D6: 3333
A7: BAH (Housing) | B7: 2741.66
A8: BAS | B8: 477
A9: OHA | B9: 0
A10: COLA | B10: 0
A11: Special Pay | B11: 0
A12: Hazard Duty Pay | B12: 0
A13: Flight Duty Pay | B13: 0
A14: Foreign Language Pay | B14: 0
A15: Family Separation Allowance | B15: 0
A16: Other Take Home Pay | B16: 0
A17: Military Retirement Pay | B17: 0
A18: Rental Home Income | B18: 0
... A20: Child Support/Alimony | B20: 0
A24: GROSS MONTHLY INCOME | B24: =SUM(B6:B23) -> 8810.32 | C24: =SUM(C6:C23) -> 9803.15 | D24: =SUM(D6:D23) -> 3333
A26: DEDUCTIONS | B26: CURRENT | C26: PROJECTED - Computer Science Job | D26: PROJECTED - Grad School
A27: FITW (Federal Income Tax Withheld) | B27: 467.6 | C27: 1238.42
A28: FICA (Social Security) | B28: 284.28 | C28: 749.92
A29: FICA (Medicare) | B29: 66.49
A30: State Income Tax | B30: 240.08 | C30: 478.75
A31: AFRH (Armed Forces Retirement Home) | B31: 0.5 | C31: 0
A32: SGLI and T-SGLI | B32: 31
A33: SGLI Family/Spouse | B33: 0
A34: TSP | C34: 0
A35: SDP | B35: 0
A36: Partial Pay | B36: 0
A37: Advance Payments | B37: 0
A38: Montgomery GI Bill | B38: 0
A39: Child Support/Alimony Paid | B39: 0
A40: 401K | C40: 541.67 | E40: USER ENTERED — monthly snapshot only. Does NOT feed PROJECTIONS. Zero out if not contributing immediately at CS job start. C45=SUM(C27:C44) includes this in net income calc for the snapshot.
A45: DEDUCTIONS | B45: =SUM(B27:B44) -> 1089.95 | C45: =SUM(C27:C44) -> 3008.76 | D45: =SUM(D27:D44) -> 0
A47: NET MONTHLY INCOME | B47: =B24-B45 -> 7720.37 | C47: =C24-C45 -> 6794.39 | D47: =D24-D45 -> 3333
A49: SPOUSE MONTHLY INCOME
A50: ENTITLEMENTS | B50: CURRENT | C50: PROJECTED - Computer Science Job | D50: PROJECTED - Grad School
A51: Monthly Pay
A52: BAH (Housing)
...

Sheet EXPENSES
A1: MONTHLY EXPENSES
A2: City or Zip Code | B2: CURRENT LOCATION | C2: POTENTIAL LOCATION | D2: POTENTIAL LOCATION
B3: =INCOME!B3 -> 0 | C3: =INCOME!C3 -> 0 | D3: =INCOME!D3 -> 0
A4: LIVING EXPENSES | B4: CURRENT | C4: PROJECTED - Computer Science Job | D4: PROJECTED - Grad School | E4: REMARKS
A5: HOUSING TOTAL | B5: =SUM(B6:B12) -> 500 | C5: =SUM(C6:C12) -> 2600 | D5: =SUM(D6:D12) -> 2580
A6: Fees/HOA Fees/Pool Fees | B6: 0 | C6: 0
A7: Furniture/Decorations | B7: 0 | C7: 0
A8: Home Maintenance/Repairs | B8: 0 | C8: 0
A9: Taxes | B9: 0 | C9: 0
A10: Rent | B10: 500 | C10: 2500 | D10: 2500 | E10: KEY: GI Bill BAH ($4,992/mo Bay Area) is income, not an expense offset. This rent IS your real cost — GI Bill covers it and more. Update to match your admitted school's market rate.
A11: Renters Insurance | C11: 100 | D11: 80 | E11: Renters insurance ~$80/mo typical
A13: UTILITIES TOTAL | B13: =SUM(B14:B20) -> 103.82 | C13: =SUM(C14:C20) -> 103.82 | D13: =SUM(D14:D20) -> 164
A14: Cable/Satellite | B14: 0 | C14: 0
A15: Cell Phone/Phone Cards/Landline | B15: 25 | C15: 25 | D15: 25 | E15: Cell phone — same as current
A16: Internet | B16: 78.82 | C16: 78.82 | D16: 79 | E16: Internet ~$79/mo — university area typical
A17: Electricity | B17: 0 | C17: 0 | D17: 60 | E17: Electricity ~$60/mo for 1BR apt
A18: Natural Gas/Propane | B18: 0 | C18: 0
A19: Garbage | B19: 0 | C19: 0
A20: Water/Sewage | B20: 0
A21: TRANSPORTATION TOTAL | B21: =SUM(B22:B29) -> 490 | C21: =SUM(C22:C29) -> 290 | D21: =SUM(D22:D29) -> 245
A22: Gasoline | B22: 400 | C22: 200 | D22: 80 | E22: Gasoline — reduced; most PhD students use transit near campus
A23: Parking | B23: 0 | C23: 0
A24: Taxes/Registration/Licensing | B24: 15 | C24: 15 | D24: 15
A25: Taxi/Bus/Uber/Lyft/Train | B25: 0 | C25: 0 | D25: 100 | E25: BART/Caltrain/bus pass ~$100-150/mo Bay Area. Many campuses subsidize.
A26: Vehicle Maintenance/Repairs | B26: 75 | C26: 75 | D26: 50 | E26: Vehicle maintenance — reduced mileage
A30: FOOD TOTAL | B30: =SUM(B31:B37) -> 540 | C30: =SUM(C31:C37) -> 540 | D30: =SUM(D31:D37) -> 640
A31: Dining out | B31: 250 | C31: 250 | D31: 200 | E31: Dining out — Bay Area PhD student estimate
A32: Groceries | B32: 250 | C32: 250 | D32: 400 | E32: Groceries — Bay Area avg ~$400/mo single person
A33: Lunches | B33: 40 | C33: 40 | D33: 40
A34: Vending Machines
A38: INSURANCE TOTAL | B38: =SUM(B39:B46) -> 182 | C38: =SUM(C39:C46) -> 802 | D38: =SUM(D39:D46) -> 165
A39: Auto Insurance | B39: 182 | C39: 150 | D39: 150 | E39: Auto insurance — reduced to minimum coverage if needed
A40: Dental Insurance | B40: 0 | C40: 20 | D40: 0 | E40: Dental — most PhD programs include dental in health plan
A41: Health Insurance | B41: 0 | C41: 580 | D41: 0 | E41: Health ins — covered by university stipend package (typical PhD benefit)
A42: Life Insurance | B42: 0 | C42: 52 | D42: 15 | E42: Life insurance ~$15/mo basic term
A43: Renters/Home Insurance | B43: 0 | C43: 0
A47: HEALTHCARE | B47: =SUM(B48:B54) -> 10 | C47: =SUM(C48:C54) -> 150 | D47: =SUM(D48:D54) -> 70
A48: Dental | B48: 0 | C48: 20 | D48: 10 | E48: Dental copays — minimal with university coverage
A49: Doctor/Hospital/Urgent Care | B49: 0 | C49: 100 | D49: 30 | E49: Doctor/urgent care copays
A50: Eye Care | B50: 0 | C50: 20 | D50: 20 | E50: Eye care annual
...

Sheet DEBT
A1: DEBT
A2: City or Zip Code | C2: CURRENT LOCATION | E2: POTENTIAL LOCATION
C3: =INCOME!B3 -> 0 | E3: =INCOME!C3 -> 0
A4: HOUSING CREDITOR | C4: CURRENT MONTHLY PAYMENT | D4: CURRENT BALANCE | E4: PROJECTED MONTHLY PAYMENT | F4: PROJECTED TOTAL COST | G4: REMARKS (MONTHS BEHIND, PAID BY ALLOTMENT, ETC.)
A5: Rent/Primary Home Mortgage
A6: Secondary Home Mortgage | C6: 0
A7: Rental Property | C7: 0
A8: Other (Vacation Home/Trailer/Time Share) | C8: 0
A10: TOTAL | C10: =SUM(C5:C9) -> 0 | D10: =SUM(D5:D9) -> 0 | E10: =SUM(E5:E9) -> 0 | F10: =SUM(F5:F9) -> 0
A12: CREDITOR | B12: PURPOSE | C12: CURRENT MONTHLY PAYMENT | D12: CURRENT BALANCE | E12: PROJECTED MONTHLY PAYMENT | F12: PROJECTED TOTAL COST | G12: REMARKS (MONTHS BEHIND, PAID BY ALLOTMENT, ETC.)
E13: 0
A29: TOTAL | C29: =SUM(C13:C28) -> 0 | D29: =SUM(D13:D28) -> 0 | E29: =SUM(E13:E28) -> 0 | F29: =SUM(F13:F28) -> 0
C31: DEBT TO INCOME RATIO CALCULATIONS
D32: CURRENT LOCATION | E32: POTENTIAL LOCATION | F32: REMARKS
C33: City or Zip Code | D33: =INCOME!B3 -> 0 | E33: =INCOME!C3 -> 0
C34: Total Gross Monthly Income | D34: =INCOME!$B97 -> 8810.32 | E34: =INCOME!C97 -> 9803.15
C35: Total Monthly Debt Payments | D35: =SUM(C10,C29) -> 0 | E35: =SUM(E10,E29) -> 0
C36: DEBT-TO-INCOME RATIO | D36: =IF(D34, D35/D34, 0) -> 0 | E36: =IF(E34, E35/E34, 0) -> 0
C37: TOTAL DEBT | D37: =SUM(D$10,D$29) -> 0 | E37: =SUM(F10,F29) -> 0
C38: (Debt-to-Income Ratio equals total monthly debt payments divided by gross income and multiplied by 100.)

Sheet ASSETS
A1: ASSETS, LIABILITIES, AND NET WORTH
A2: City or Zip Code | B2: CURRENT LOCATION
B3: 95835
A4: ASSETS | B4: CURRENT | C4: REMARKS
A5: SAVINGS | B5: =SUM(B6:B22) -> 150000
A6: Cash on Hand
A7: Checking Accounts | B7: 8000
A8: Savings Accounts | B8: 12000
A9: Emergency Savings
A10: TSP | B10: 75000 | C10: All in Roth, currently ~1900/month
A11: Certificates of Deposit (CDs)
A12: Cash Value of Life Insurance
A13: U.S. Savings Bonds
A14: Money Market Accounts
A15: Mutual Funds
A16: Stocks/Bonds
A17: College Funds
A18: 401(k)/403(b)
A19: Roth IRA | B19: 30000 | C19: Not Invested.
A20: Brokerage | B20: 25000 | C20: Not Invested.
A23: REAL ESTATE (MARKET VALUE) | B23: =SUM(B24:B29) -> 0
A24: Primary Home
A25: Secondary Home
A26: Rental Property
A30: PERSONAL PROPERTY | B30: =SUM(B31:B36) -> 25000
A31: Vehicles/Motorcycles/Boats | B31: 25000
A32: Furniture
A33: Jewelry
A37: TOTAL ASSETS | B37: =SUM(B5,B23,B30) -> 175000
A39: LIABILITIES | B39: CURRENT | C39: REMARKS
A40: TOTAL DEBT | B40: =DEBT!$D37 -> 0
A42: NET WORTH (ASSETS - LIABILITIES) | B42: CURRENT | C42: REMARKS
B43: =B37-B40 -> 175000

Sheet SUMMARY AND ACTION PLAN
A1: SUMMARY
A2: City or Zip Code | B2: CURRENT LOCATION | C2: PROJECTED - Computer Science Job | D2: PROJECTED - Grad School
B3: =INCOME!B3 -> 0 | C3: =INCOME!C3 -> 0 | D3: =INCOME!D3 -> 0
A4: Monthly
A5: Gross Income | B5: =INCOME!B97 -> 8810.32 | C5: =INCOME!C97 -> 9803.15 | D5: =INCOME!D97 -> 3333
A6: NET Income | B6: =INCOME!B99 -> 7720.37 | C6: =INCOME!C99 -> 6794.39 | D6: =INCOME!D99 -> 3333
A7: Living Expenses | B7: =EXPENSES!B126 -> 2393.82 | C7: =EXPENSES!C126 -> 5053.82 | D7: =EXPENSES!D126 -> 4152
A8: Debt Payments | B8: =DEBT!D35 -> 0 | C8: =DEBT!E35 -> 0 | D8: =DEBT!E35 -> 0
A9: MONTHLY SURPLUS OR DEFICIT | B9: =B6-B7-B8 -> 5326.55 | C9: =C6-C7-C8 -> 1740.57 | D9: =D6-D7-D8 -> -819
A10: DEBT-TO-INCOME RATIO | B10: =DEBT!D36 -> 0 | C10: =DEBT!E36 -> 0 | D10: =DEBT!E36 -> 0
A17: ACTION PLAN
A18: INCREASE INCOME
A20: DECREASE LIVING EXPENSES
A22: DECREASE DEBT
A25: PLANNING ITEMS & MODEL GAPS
A26: # | B26: Category | C26: Item | D26: Status
A27: 1 | B27: VERIFY | C27: Verify actual pension estimate at DFAS calculator (mypay.dfas.mil) — current model uses estimated E-8 High-3 | D27: Open
A28: 2 | B28: VERIFY | C28: Confirm GI Bill BAH rate for actual admitted school (CMU ~$1,400/mo vs Bay Area $4,992/mo — $43K/yr difference) | D28: Open
A29: 3 | B29: GAP | C29: Add Social Security projections — Path B longer civilian career = higher SS benefit; both paths qualify | D29: Not modeled
A30: 4 | B30: GAP | C30: Housing costs not accurately modeled for all phases — Path A PhD (2035-2039) and Path B PhD (2028-2032) need school-specific rent | D30: Partially modeled
A31: 5 | B31: GAP | C31: Warrant Officer path not modeled — different pay trajectory than E-7; add as Path C if seriously considered | D31: Not modeled
A32: 6 | B32: GAP | C32: Microsoft/civilian path (no PhD) not modeled — $117K starting vs $220K post-PhD; add as Path C or D | D32: Not modeled
A33: 7 | B33: GAP | C33: GI Bill BAH duration: modeled as 3 years (rows 7-9 in PROJECTIONS) — verify this matches actual 36-month eligibility | D33: Review
A34: 8 | B34: SENSITIVITY | C34: VA disability sensitivity analysis — model 10%, 20%, 30%, 40%, 50% ratings side by side | D34: Not modeled
A35: 9 | B35: SENSITIVITY | C35: Investment return sensitivity — model optimistic (9%), base (7%), pessimistic (5%) scenarios | D35: Not modeled
A36: 10 | B36: TRACKING | C36: Salary actuals tracking — add section to record actual vs projected income each year as career progresses | D36: Open
A37: 11 | B37: TRACKING | C37: Salary benchmark note: $220K is conservative post-PhD; DeepMind avg $264K, Anthropic median $442K (research scientist) | D37: Informational
A38: 12 | B38: CONCERN | C38: Path A PhD years 2038-2039 show negative cash flow — GI Bill BAH ends, pension + stipend may not cover Bay Area expenses | D38: Flag
